2023-07-21 14:47:55,752 ERROR scheduler Exception in Enqueue Events for Site erp.aurumwholesale.com
Traceback (most recent call last):
  File "apps/frappe/frappe/utils/scheduler.py", line 70, in enqueue_events_for_site
    if is_scheduler_inactive():
  File "apps/frappe/frappe/utils/scheduler.py", line 109, in is_scheduler_inactive
    if is_scheduler_disabled(verbose=verbose):
  File "apps/frappe/frappe/utils/scheduler.py", line 122, in is_scheduler_disabled
    frappe.db.get_single_value("System Settings", "enable_scheduler")
  File "apps/frappe/frappe/database/database.py", line 789, in get_single_value
    df = frappe.get_meta(doctype).get_field(fieldname)
  File "apps/frappe/frappe/__init__.py", line 1214, in get_meta
    return frappe.model.meta.get_meta(doctype, cached=cached)
  File "apps/frappe/frappe/model/meta.py", line 65, in get_meta
    meta = Meta(doctype)
  File "apps/frappe/frappe/model/meta.py", line 117, in __init__
    super().__init__("DocType", doctype)
  File "apps/frappe/frappe/model/document.py", line 106, in __init__
    self.load_from_db()
  File "apps/frappe/frappe/model/meta.py", line 123, in load_from_db
    super().load_from_db()
  File "apps/frappe/frappe/model/document.py", line 149, in load_from_db
    frappe.throw(
  File "apps/frappe/frappe/__init__.py", line 528, in throw
    msgprint(
  File "apps/frappe/frappe/__init__.py", line 496, in msgprint
    _raise_exception()
  File "apps/frappe/frappe/__init__.py", line 445, in _raise_exception
    raise raise_exception(msg)
frappe.exceptions.DoesNotExistError: DocType System Settings not found

2023-07-23 19:10:59,521 ERROR scheduler Exception in Enqueue Events for Site erp.1click.com
Traceback (most recent call last):
  File "env/lib/python3.10/site-packages/rq/job.py", line 552, in restore
    raw_data = obj['data']
KeyError: 'data'

During handling of the above exception, another exception occurred:

Traceback (most recent call last):
  File "apps/frappe/frappe/utils/scheduler.py", line 73, in enqueue_events_for_site
    enqueue_events(site=site)
  File "apps/frappe/frappe/utils/scheduler.py", line 91, in enqueue_events
    queued_jobs = get_jobs(site=site, key="job_type").get(site) or []
  File "apps/frappe/frappe/utils/background_jobs.py", line 299, in get_jobs
    jobs = q.jobs + get_running_jobs_in_queue(q)
  File "apps/frappe/frappe/utils/background_jobs.py", line 338, in get_running_jobs_in_queue
    current_job = worker.get_current_job()
  File "env/lib/python3.10/site-packages/rq/worker.py", line 421, in get_current_job
    return self.job_class.fetch(job_id, self.connection, self.serializer)
  File "env/lib/python3.10/site-packages/rq/job.py", line 372, in fetch
    job.refresh()
  File "env/lib/python3.10/site-packages/rq/job.py", line 618, in refresh
    self.restore(data)
  File "env/lib/python3.10/site-packages/rq/job.py", line 554, in restore
    raise NoSuchJobError('Unexpected job format: {0}'.format(obj))
rq.exceptions.NoSuchJobError: Unexpected job format: {'worker_name': b'83127190d2ea438db5417600bec5b5f0.ubuntupc.1466.home-admin123-frappe-bench:default', 'status': b'started', 'started_at': b'2023-07-24T00:10:59.512741Z', 'last_heartbeat': b'2023-07-24T00:10:59.512741Z'}

2023-07-23 19:10:59,529 ERROR scheduler Exception in Enqueue Events for Site erp.aurumwholesale.com
Traceback (most recent call last):
  File "env/lib/python3.10/site-packages/rq/job.py", line 552, in restore
    raw_data = obj['data']
KeyError: 'data'

During handling of the above exception, another exception occurred:

Traceback (most recent call last):
  File "apps/frappe/frappe/utils/scheduler.py", line 73, in enqueue_events_for_site
    enqueue_events(site=site)
  File "apps/frappe/frappe/utils/scheduler.py", line 91, in enqueue_events
    queued_jobs = get_jobs(site=site, key="job_type").get(site) or []
  File "apps/frappe/frappe/utils/background_jobs.py", line 299, in get_jobs
    jobs = q.jobs + get_running_jobs_in_queue(q)
  File "apps/frappe/frappe/utils/background_jobs.py", line 338, in get_running_jobs_in_queue
    current_job = worker.get_current_job()
  File "env/lib/python3.10/site-packages/rq/worker.py", line 421, in get_current_job
    return self.job_class.fetch(job_id, self.connection, self.serializer)
  File "env/lib/python3.10/site-packages/rq/job.py", line 372, in fetch
    job.refresh()
  File "env/lib/python3.10/site-packages/rq/job.py", line 618, in refresh
    self.restore(data)
  File "env/lib/python3.10/site-packages/rq/job.py", line 554, in restore
    raise NoSuchJobError('Unexpected job format: {0}'.format(obj))
rq.exceptions.NoSuchJobError: Unexpected job format: {'worker_name': b'83127190d2ea438db5417600bec5b5f0.ubuntupc.1466.home-admin123-frappe-bench:default', 'status': b'started', 'started_at': b'2023-07-24T00:10:59.512741Z', 'last_heartbeat': b'2023-07-24T00:10:59.512741Z'}

2023-07-23 19:10:59,541 ERROR scheduler Exception in Enqueue Events for Site erp.echemportal.com
Traceback (most recent call last):
  File "env/lib/python3.10/site-packages/rq/job.py", line 552, in restore
    raw_data = obj['data']
KeyError: 'data'

During handling of the above exception, another exception occurred:

Traceback (most recent call last):
  File "apps/frappe/frappe/utils/scheduler.py", line 73, in enqueue_events_for_site
    enqueue_events(site=site)
  File "apps/frappe/frappe/utils/scheduler.py", line 91, in enqueue_events
    queued_jobs = get_jobs(site=site, key="job_type").get(site) or []
  File "apps/frappe/frappe/utils/background_jobs.py", line 299, in get_jobs
    jobs = q.jobs + get_running_jobs_in_queue(q)
  File "apps/frappe/frappe/utils/background_jobs.py", line 338, in get_running_jobs_in_queue
    current_job = worker.get_current_job()
  File "env/lib/python3.10/site-packages/rq/worker.py", line 421, in get_current_job
    return self.job_class.fetch(job_id, self.connection, self.serializer)
  File "env/lib/python3.10/site-packages/rq/job.py", line 372, in fetch
    job.refresh()
  File "env/lib/python3.10/site-packages/rq/job.py", line 618, in refresh
    self.restore(data)
  File "env/lib/python3.10/site-packages/rq/job.py", line 554, in restore
    raise NoSuchJobError('Unexpected job format: {0}'.format(obj))
rq.exceptions.NoSuchJobError: Unexpected job format: {'worker_name': b'83127190d2ea438db5417600bec5b5f0.ubuntupc.1466.home-admin123-frappe-bench:default', 'status': b'started', 'started_at': b'2023-07-24T00:10:59.512741Z', 'last_heartbeat': b'2023-07-24T00:10:59.512741Z'}

2023-07-23 19:10:59,549 ERROR scheduler Exception in Enqueue Events for Site erpenzemic.mol-tech.com
Traceback (most recent call last):
  File "env/lib/python3.10/site-packages/rq/job.py", line 552, in restore
    raw_data = obj['data']
KeyError: 'data'

During handling of the above exception, another exception occurred:

Traceback (most recent call last):
  File "apps/frappe/frappe/utils/scheduler.py", line 73, in enqueue_events_for_site
    enqueue_events(site=site)
  File "apps/frappe/frappe/utils/scheduler.py", line 91, in enqueue_events
    queued_jobs = get_jobs(site=site, key="job_type").get(site) or []
  File "apps/frappe/frappe/utils/background_jobs.py", line 299, in get_jobs
    jobs = q.jobs + get_running_jobs_in_queue(q)
  File "apps/frappe/frappe/utils/background_jobs.py", line 338, in get_running_jobs_in_queue
    current_job = worker.get_current_job()
  File "env/lib/python3.10/site-packages/rq/worker.py", line 421, in get_current_job
    return self.job_class.fetch(job_id, self.connection, self.serializer)
  File "env/lib/python3.10/site-packages/rq/job.py", line 372, in fetch
    job.refresh()
  File "env/lib/python3.10/site-packages/rq/job.py", line 618, in refresh
    self.restore(data)
  File "env/lib/python3.10/site-packages/rq/job.py", line 554, in restore
    raise NoSuchJobError('Unexpected job format: {0}'.format(obj))
rq.exceptions.NoSuchJobError: Unexpected job format: {'worker_name': b'83127190d2ea438db5417600bec5b5f0.ubuntupc.1466.home-admin123-frappe-bench:default', 'status': b'started', 'started_at': b'2023-07-24T00:10:59.512741Z', 'last_heartbeat': b'2023-07-24T00:10:59.512741Z'}

2023-09-30 15:21:04,369 ERROR scheduler Exception in Enqueue Events for Site erp.aurumwholesale.com
Traceback (most recent call last):
  File "apps/frappe/frappe/utils/scheduler.py", line 70, in enqueue_events_for_site
    if is_scheduler_inactive():
  File "apps/frappe/frappe/utils/scheduler.py", line 109, in is_scheduler_inactive
    if is_scheduler_disabled(verbose=verbose):
  File "apps/frappe/frappe/utils/scheduler.py", line 122, in is_scheduler_disabled
    frappe.db.get_single_value("System Settings", "enable_scheduler")
  File "apps/frappe/frappe/database/database.py", line 789, in get_single_value
    df = frappe.get_meta(doctype).get_field(fieldname)
  File "apps/frappe/frappe/__init__.py", line 1214, in get_meta
    return frappe.model.meta.get_meta(doctype, cached=cached)
  File "apps/frappe/frappe/model/meta.py", line 65, in get_meta
    meta = Meta(doctype)
  File "apps/frappe/frappe/model/meta.py", line 117, in __init__
    super().__init__("DocType", doctype)
  File "apps/frappe/frappe/model/document.py", line 106, in __init__
    self.load_from_db()
  File "apps/frappe/frappe/model/meta.py", line 123, in load_from_db
    super().load_from_db()
  File "apps/frappe/frappe/model/document.py", line 149, in load_from_db
    frappe.throw(
  File "apps/frappe/frappe/__init__.py", line 528, in throw
    msgprint(
  File "apps/frappe/frappe/__init__.py", line 496, in msgprint
    _raise_exception()
  File "apps/frappe/frappe/__init__.py", line 445, in _raise_exception
    raise raise_exception(msg)
frappe.exceptions.DoesNotExistError: DocType System Settings not found

2023-11-21 15:33:05,484 ERROR scheduler Exception in Enqueue Events for Site erp.aurumwholesale.com
Traceback (most recent call last):
  File "env/lib/python3.10/site-packages/redis/connection.py", line 559, in connect
    sock = self._connect()
  File "env/lib/python3.10/site-packages/redis/connection.py", line 615, in _connect
    raise err
  File "env/lib/python3.10/site-packages/redis/connection.py", line 603, in _connect
    sock.connect(socket_address)
ConnectionRefusedError: [Errno 111] Connection refused

During handling of the above exception, another exception occurred:

Traceback (most recent call last):
  File "env/lib/python3.10/site-packages/tenacity/__init__.py", line 407, in __call__
    result = fn(*args, **kwargs)
  File "apps/frappe/frappe/utils/background_jobs.py", line 388, in get_redis_conn
    _redis_queue_conn = RedisQueue.get_connection()
  File "apps/frappe/frappe/utils/redis_queue.py", line 24, in get_connection
    conn.ping()
  File "env/lib/python3.10/site-packages/redis/client.py", line 1378, in ping
    return self.execute_command('PING')
  File "env/lib/python3.10/site-packages/redis/client.py", line 898, in execute_command
    conn = self.connection or pool.get_connection(command_name, **options)
  File "env/lib/python3.10/site-packages/redis/connection.py", line 1192, in get_connection
    connection.connect()
  File "env/lib/python3.10/site-packages/redis/connection.py", line 563, in connect
    raise ConnectionError(self._error_message(e))
redis.exceptions.ConnectionError: Error 111 connecting to localhost:11000. Connection refused.

The above exception was the direct cause of the following exception:

Traceback (most recent call last):
  File "apps/frappe/frappe/utils/scheduler.py", line 73, in enqueue_events_for_site
    enqueue_events(site=site)
  File "apps/frappe/frappe/utils/scheduler.py", line 91, in enqueue_events
    queued_jobs = get_jobs(site=site, key="job_type").get(site) or []
  File "apps/frappe/frappe/utils/background_jobs.py", line 298, in get_jobs
    q = get_queue(_queue)
  File "apps/frappe/frappe/utils/background_jobs.py", line 347, in get_queue
    return Queue(generate_qname(qtype), connection=get_redis_conn(), is_async=is_async)
  File "env/lib/python3.10/site-packages/tenacity/__init__.py", line 324, in wrapped_f
    return self(f, *args, **kw)
  File "env/lib/python3.10/site-packages/tenacity/__init__.py", line 404, in __call__
    do = self.iter(retry_state=retry_state)
  File "env/lib/python3.10/site-packages/tenacity/__init__.py", line 361, in iter
    raise retry_exc from fut.exception()
tenacity.RetryError: RetryError[<Future at 0x7fd994afac20 state=finished raised ConnectionError>]

2023-12-26 12:23:36,544 ERROR scheduler Exception in Enqueue Events for Site trial.aurumwholesale.com
Traceback (most recent call last):
  File "apps/frappe/frappe/utils/scheduler.py", line 70, in enqueue_events_for_site
    if is_scheduler_inactive():
  File "apps/frappe/frappe/utils/scheduler.py", line 109, in is_scheduler_inactive
    if is_scheduler_disabled(verbose=verbose):
  File "apps/frappe/frappe/utils/scheduler.py", line 122, in is_scheduler_disabled
    frappe.db.get_single_value("System Settings", "enable_scheduler")
  File "apps/frappe/frappe/database/database.py", line 789, in get_single_value
    df = frappe.get_meta(doctype).get_field(fieldname)
  File "apps/frappe/frappe/__init__.py", line 1214, in get_meta
    return frappe.model.meta.get_meta(doctype, cached=cached)
  File "apps/frappe/frappe/model/meta.py", line 65, in get_meta
    meta = Meta(doctype)
  File "apps/frappe/frappe/model/meta.py", line 117, in __init__
    super().__init__("DocType", doctype)
  File "apps/frappe/frappe/model/document.py", line 106, in __init__
    self.load_from_db()
  File "apps/frappe/frappe/model/meta.py", line 123, in load_from_db
    super().load_from_db()
  File "apps/frappe/frappe/model/document.py", line 149, in load_from_db
    frappe.throw(
  File "apps/frappe/frappe/__init__.py", line 528, in throw
    msgprint(
  File "apps/frappe/frappe/__init__.py", line 496, in msgprint
    _raise_exception()
  File "apps/frappe/frappe/__init__.py", line 445, in _raise_exception
    raise raise_exception(msg)
frappe.exceptions.DoesNotExistError: DocType System Settings not found

2023-12-26 15:30:26,983 ERROR scheduler Exception in Enqueue Events for Site erp.echemportal.com
Traceback (most recent call last):
  File "apps/frappe/frappe/utils/scheduler.py", line 70, in enqueue_events_for_site
    if is_scheduler_inactive():
  File "apps/frappe/frappe/utils/scheduler.py", line 109, in is_scheduler_inactive
    if is_scheduler_disabled(verbose=verbose):
  File "apps/frappe/frappe/utils/scheduler.py", line 122, in is_scheduler_disabled
    frappe.db.get_single_value("System Settings", "enable_scheduler")
  File "apps/frappe/frappe/database/database.py", line 789, in get_single_value
    df = frappe.get_meta(doctype).get_field(fieldname)
  File "apps/frappe/frappe/__init__.py", line 1214, in get_meta
    return frappe.model.meta.get_meta(doctype, cached=cached)
  File "apps/frappe/frappe/model/meta.py", line 65, in get_meta
    meta = Meta(doctype)
  File "apps/frappe/frappe/model/meta.py", line 117, in __init__
    super().__init__("DocType", doctype)
  File "apps/frappe/frappe/model/document.py", line 106, in __init__
    self.load_from_db()
  File "apps/frappe/frappe/model/meta.py", line 123, in load_from_db
    super().load_from_db()
  File "apps/frappe/frappe/model/document.py", line 149, in load_from_db
    frappe.throw(
  File "apps/frappe/frappe/__init__.py", line 528, in throw
    msgprint(
  File "apps/frappe/frappe/__init__.py", line 496, in msgprint
    _raise_exception()
  File "apps/frappe/frappe/__init__.py", line 445, in _raise_exception
    raise raise_exception(msg)
frappe.exceptions.DoesNotExistError: DocType System Settings not found

