/usr/lib/python3.10/functools.py:981: UserWarning: The 'filters_config' hook used to add custom operators is not yet implemented in frappe.db.query engine. Use db_query (frappe.get_list) instead.
  val = self.func(instance)
/usr/lib/python3.10/functools.py:981: UserWarning: The 'filters_config' hook used to add custom operators is not yet implemented in frappe.db.query engine. Use db_query (frappe.get_list) instead.
  val = self.func(instance)
/usr/lib/python3.10/functools.py:981: UserWarning: The 'filters_config' hook used to add custom operators is not yet implemented in frappe.db.query engine. Use db_query (frappe.get_list) instead.
  val = self.func(instance)
/usr/lib/python3.10/functools.py:981: UserWarning: The 'filters_config' hook used to add custom operators is not yet implemented in frappe.db.query engine. Use db_query (frappe.get_list) instead.
  val = self.func(instance)
/usr/lib/python3.10/functools.py:981: UserWarning: The 'filters_config' hook used to add custom operators is not yet implemented in frappe.db.query engine. Use db_query (frappe.get_list) instead.
  val = self.func(instance)
/usr/lib/python3.10/functools.py:981: UserWarning: The 'filters_config' hook used to add custom operators is not yet implemented in frappe.db.query engine. Use db_query (frappe.get_list) instead.
  val = self.func(instance)
/usr/lib/python3.10/functools.py:981: UserWarning: The 'filters_config' hook used to add custom operators is not yet implemented in frappe.db.query engine. Use db_query (frappe.get_list) instead.
  val = self.func(instance)
/usr/lib/python3.10/functools.py:981: UserWarning: The 'filters_config' hook used to add custom operators is not yet implemented in frappe.db.query engine. Use db_query (frappe.get_list) instead.
  val = self.func(instance)
/usr/lib/python3.10/functools.py:981: UserWarning: The 'filters_config' hook used to add custom operators is not yet implemented in frappe.db.query engine. Use db_query (frappe.get_list) instead.
  val = self.func(instance)
/usr/lib/python3.10/functools.py:981: UserWarning: The 'filters_config' hook used to add custom operators is not yet implemented in frappe.db.query engine. Use db_query (frappe.get_list) instead.
  val = self.func(instance)
/usr/lib/python3.10/functools.py:981: UserWarning: The 'filters_config' hook used to add custom operators is not yet implemented in frappe.db.query engine. Use db_query (frappe.get_list) instead.
  val = self.func(instance)
/usr/lib/python3.10/functools.py:981: UserWarning: The 'filters_config' hook used to add custom operators is not yet implemented in frappe.db.query engine. Use db_query (frappe.get_list) instead.
  val = self.func(instance)
/usr/lib/python3.10/functools.py:981: UserWarning: The 'filters_config' hook used to add custom operators is not yet implemented in frappe.db.query engine. Use db_query (frappe.get_list) instead.
  val = self.func(instance)
/usr/lib/python3.10/functools.py:981: UserWarning: The 'filters_config' hook used to add custom operators is not yet implemented in frappe.db.query engine. Use db_query (frappe.get_list) instead.
  val = self.func(instance)
/usr/lib/python3.10/functools.py:981: UserWarning: The 'filters_config' hook used to add custom operators is not yet implemented in frappe.db.query engine. Use db_query (frappe.get_list) instead.
  val = self.func(instance)
/usr/lib/python3.10/functools.py:981: UserWarning: The 'filters_config' hook used to add custom operators is not yet implemented in frappe.db.query engine. Use db_query (frappe.get_list) instead.
  val = self.func(instance)
/usr/lib/python3.10/functools.py:981: UserWarning: The 'filters_config' hook used to add custom operators is not yet implemented in frappe.db.query engine. Use db_query (frappe.get_list) instead.
  val = self.func(instance)
/usr/lib/python3.10/functools.py:981: UserWarning: The 'filters_config' hook used to add custom operators is not yet implemented in frappe.db.query engine. Use db_query (frappe.get_list) instead.
  val = self.func(instance)
/usr/lib/python3.10/functools.py:981: UserWarning: The 'filters_config' hook used to add custom operators is not yet implemented in frappe.db.query engine. Use db_query (frappe.get_list) instead.
  val = self.func(instance)
/usr/lib/python3.10/functools.py:981: UserWarning: The 'filters_config' hook used to add custom operators is not yet implemented in frappe.db.query engine. Use db_query (frappe.get_list) instead.
  val = self.func(instance)
/usr/lib/python3.10/functools.py:981: UserWarning: The 'filters_config' hook used to add custom operators is not yet implemented in frappe.db.query engine. Use db_query (frappe.get_list) instead.
  val = self.func(instance)
/usr/lib/python3.10/functools.py:981: UserWarning: The 'filters_config' hook used to add custom operators is not yet implemented in frappe.db.query engine. Use db_query (frappe.get_list) instead.
  val = self.func(instance)
/usr/lib/python3.10/functools.py:981: UserWarning: The 'filters_config' hook used to add custom operators is not yet implemented in frappe.db.query engine. Use db_query (frappe.get_list) instead.
  val = self.func(instance)
/usr/lib/python3.10/functools.py:981: UserWarning: The 'filters_config' hook used to add custom operators is not yet implemented in frappe.db.query engine. Use db_query (frappe.get_list) instead.
  val = self.func(instance)
/usr/lib/python3.10/functools.py:981: UserWarning: The 'filters_config' hook used to add custom operators is not yet implemented in frappe.db.query engine. Use db_query (frappe.get_list) instead.
  val = self.func(instance)
/usr/lib/python3.10/functools.py:981: UserWarning: The 'filters_config' hook used to add custom operators is not yet implemented in frappe.db.query engine. Use db_query (frappe.get_list) instead.
  val = self.func(instance)
/usr/lib/python3.10/functools.py:981: UserWarning: The 'filters_config' hook used to add custom operators is not yet implemented in frappe.db.query engine. Use db_query (frappe.get_list) instead.
  val = self.func(instance)
/usr/lib/python3.10/functools.py:981: UserWarning: The 'filters_config' hook used to add custom operators is not yet implemented in frappe.db.query engine. Use db_query (frappe.get_list) instead.
  val = self.func(instance)
/usr/lib/python3.10/functools.py:981: UserWarning: The 'filters_config' hook used to add custom operators is not yet implemented in frappe.db.query engine. Use db_query (frappe.get_list) instead.
  val = self.func(instance)
/usr/lib/python3.10/functools.py:981: UserWarning: The 'filters_config' hook used to add custom operators is not yet implemented in frappe.db.query engine. Use db_query (frappe.get_list) instead.
  val = self.func(instance)
/usr/lib/python3.10/functools.py:981: UserWarning: The 'filters_config' hook used to add custom operators is not yet implemented in frappe.db.query engine. Use db_query (frappe.get_list) instead.
  val = self.func(instance)
/usr/lib/python3.10/functools.py:981: UserWarning: The 'filters_config' hook used to add custom operators is not yet implemented in frappe.db.query engine. Use db_query (frappe.get_list) instead.
  val = self.func(instance)
/usr/lib/python3.10/functools.py:981: UserWarning: The 'filters_config' hook used to add custom operators is not yet implemented in frappe.db.query engine. Use db_query (frappe.get_list) instead.
  val = self.func(instance)
/usr/lib/python3.10/functools.py:981: UserWarning: The 'filters_config' hook used to add custom operators is not yet implemented in frappe.db.query engine. Use db_query (frappe.get_list) instead.
  val = self.func(instance)
/usr/lib/python3.10/functools.py:981: UserWarning: The 'filters_config' hook used to add custom operators is not yet implemented in frappe.db.query engine. Use db_query (frappe.get_list) instead.
  val = self.func(instance)
/usr/lib/python3.10/functools.py:981: UserWarning: The 'filters_config' hook used to add custom operators is not yet implemented in frappe.db.query engine. Use db_query (frappe.get_list) instead.
  val = self.func(instance)
/usr/lib/python3.10/functools.py:981: UserWarning: The 'filters_config' hook used to add custom operators is not yet implemented in frappe.db.query engine. Use db_query (frappe.get_list) instead.
  val = self.func(instance)
/usr/lib/python3.10/functools.py:981: UserWarning: The 'filters_config' hook used to add custom operators is not yet implemented in frappe.db.query engine. Use db_query (frappe.get_list) instead.
  val = self.func(instance)
/usr/lib/python3.10/functools.py:981: UserWarning: The 'filters_config' hook used to add custom operators is not yet implemented in frappe.db.query engine. Use db_query (frappe.get_list) instead.
  val = self.func(instance)
/usr/lib/python3.10/functools.py:981: UserWarning: The 'filters_config' hook used to add custom operators is not yet implemented in frappe.db.query engine. Use db_query (frappe.get_list) instead.
  val = self.func(instance)
/usr/lib/python3.10/functools.py:981: UserWarning: The 'filters_config' hook used to add custom operators is not yet implemented in frappe.db.query engine. Use db_query (frappe.get_list) instead.
  val = self.func(instance)
/usr/lib/python3.10/functools.py:981: UserWarning: The 'filters_config' hook used to add custom operators is not yet implemented in frappe.db.query engine. Use db_query (frappe.get_list) instead.
  val = self.func(instance)
/usr/lib/python3.10/functools.py:981: UserWarning: The 'filters_config' hook used to add custom operators is not yet implemented in frappe.db.query engine. Use db_query (frappe.get_list) instead.
  val = self.func(instance)
/usr/lib/python3.10/functools.py:981: UserWarning: The 'filters_config' hook used to add custom operators is not yet implemented in frappe.db.query engine. Use db_query (frappe.get_list) instead.
  val = self.func(instance)
/usr/lib/python3.10/functools.py:981: UserWarning: The 'filters_config' hook used to add custom operators is not yet implemented in frappe.db.query engine. Use db_query (frappe.get_list) instead.
  val = self.func(instance)
/usr/lib/python3.10/functools.py:981: UserWarning: The 'filters_config' hook used to add custom operators is not yet implemented in frappe.db.query engine. Use db_query (frappe.get_list) instead.
  val = self.func(instance)
/usr/lib/python3.10/functools.py:981: UserWarning: The 'filters_config' hook used to add custom operators is not yet implemented in frappe.db.query engine. Use db_query (frappe.get_list) instead.
  val = self.func(instance)
/usr/lib/python3.10/functools.py:981: UserWarning: The 'filters_config' hook used to add custom operators is not yet implemented in frappe.db.query engine. Use db_query (frappe.get_list) instead.
  val = self.func(instance)
/usr/lib/python3.10/functools.py:981: UserWarning: The 'filters_config' hook used to add custom operators is not yet implemented in frappe.db.query engine. Use db_query (frappe.get_list) instead.
  val = self.func(instance)
/usr/lib/python3.10/functools.py:981: UserWarning: The 'filters_config' hook used to add custom operators is not yet implemented in frappe.db.query engine. Use db_query (frappe.get_list) instead.
  val = self.func(instance)
/usr/lib/python3.10/functools.py:981: UserWarning: The 'filters_config' hook used to add custom operators is not yet implemented in frappe.db.query engine. Use db_query (frappe.get_list) instead.
  val = self.func(instance)
/usr/lib/python3.10/functools.py:981: UserWarning: The 'filters_config' hook used to add custom operators is not yet implemented in frappe.db.query engine. Use db_query (frappe.get_list) instead.
  val = self.func(instance)
/usr/lib/python3.10/functools.py:981: UserWarning: The 'filters_config' hook used to add custom operators is not yet implemented in frappe.db.query engine. Use db_query (frappe.get_list) instead.
  val = self.func(instance)
/usr/lib/python3.10/functools.py:981: UserWarning: The 'filters_config' hook used to add custom operators is not yet implemented in frappe.db.query engine. Use db_query (frappe.get_list) instead.
  val = self.func(instance)
/usr/lib/python3.10/functools.py:981: UserWarning: The 'filters_config' hook used to add custom operators is not yet implemented in frappe.db.query engine. Use db_query (frappe.get_list) instead.
  val = self.func(instance)
/usr/lib/python3.10/functools.py:981: UserWarning: The 'filters_config' hook used to add custom operators is not yet implemented in frappe.db.query engine. Use db_query (frappe.get_list) instead.
  val = self.func(instance)
/usr/lib/python3.10/functools.py:981: UserWarning: The 'filters_config' hook used to add custom operators is not yet implemented in frappe.db.query engine. Use db_query (frappe.get_list) instead.
  val = self.func(instance)
/usr/lib/python3.10/functools.py:981: UserWarning: The 'filters_config' hook used to add custom operators is not yet implemented in frappe.db.query engine. Use db_query (frappe.get_list) instead.
  val = self.func(instance)
/usr/lib/python3.10/functools.py:981: UserWarning: The 'filters_config' hook used to add custom operators is not yet implemented in frappe.db.query engine. Use db_query (frappe.get_list) instead.
  val = self.func(instance)
/usr/lib/python3.10/functools.py:981: UserWarning: The 'filters_config' hook used to add custom operators is not yet implemented in frappe.db.query engine. Use db_query (frappe.get_list) instead.
  val = self.func(instance)
/usr/lib/python3.10/functools.py:981: UserWarning: The 'filters_config' hook used to add custom operators is not yet implemented in frappe.db.query engine. Use db_query (frappe.get_list) instead.
  val = self.func(instance)
/usr/lib/python3.10/functools.py:981: UserWarning: The 'filters_config' hook used to add custom operators is not yet implemented in frappe.db.query engine. Use db_query (frappe.get_list) instead.
  val = self.func(instance)
/usr/lib/python3.10/functools.py:981: UserWarning: The 'filters_config' hook used to add custom operators is not yet implemented in frappe.db.query engine. Use db_query (frappe.get_list) instead.
  val = self.func(instance)
/usr/lib/python3.10/functools.py:981: UserWarning: The 'filters_config' hook used to add custom operators is not yet implemented in frappe.db.query engine. Use db_query (frappe.get_list) instead.
  val = self.func(instance)
/usr/lib/python3.10/functools.py:981: UserWarning: The 'filters_config' hook used to add custom operators is not yet implemented in frappe.db.query engine. Use db_query (frappe.get_list) instead.
  val = self.func(instance)
/usr/lib/python3.10/functools.py:981: UserWarning: The 'filters_config' hook used to add custom operators is not yet implemented in frappe.db.query engine. Use db_query (frappe.get_list) instead.
  val = self.func(instance)
/usr/lib/python3.10/functools.py:981: UserWarning: The 'filters_config' hook used to add custom operators is not yet implemented in frappe.db.query engine. Use db_query (frappe.get_list) instead.
  val = self.func(instance)
/usr/lib/python3.10/functools.py:981: UserWarning: The 'filters_config' hook used to add custom operators is not yet implemented in frappe.db.query engine. Use db_query (frappe.get_list) instead.
  val = self.func(instance)
/usr/lib/python3.10/functools.py:981: UserWarning: The 'filters_config' hook used to add custom operators is not yet implemented in frappe.db.query engine. Use db_query (frappe.get_list) instead.
  val = self.func(instance)
/usr/lib/python3.10/functools.py:981: UserWarning: The 'filters_config' hook used to add custom operators is not yet implemented in frappe.db.query engine. Use db_query (frappe.get_list) instead.
  val = self.func(instance)
/usr/lib/python3.10/functools.py:981: UserWarning: The 'filters_config' hook used to add custom operators is not yet implemented in frappe.db.query engine. Use db_query (frappe.get_list) instead.
  val = self.func(instance)
/usr/lib/python3.10/functools.py:981: UserWarning: The 'filters_config' hook used to add custom operators is not yet implemented in frappe.db.query engine. Use db_query (frappe.get_list) instead.
  val = self.func(instance)
/usr/lib/python3.10/functools.py:981: UserWarning: The 'filters_config' hook used to add custom operators is not yet implemented in frappe.db.query engine. Use db_query (frappe.get_list) instead.
  val = self.func(instance)
/usr/lib/python3.10/functools.py:981: UserWarning: The 'filters_config' hook used to add custom operators is not yet implemented in frappe.db.query engine. Use db_query (frappe.get_list) instead.
  val = self.func(instance)
/usr/lib/python3.10/functools.py:981: UserWarning: The 'filters_config' hook used to add custom operators is not yet implemented in frappe.db.query engine. Use db_query (frappe.get_list) instead.
  val = self.func(instance)
/usr/lib/python3.10/functools.py:981: UserWarning: The 'filters_config' hook used to add custom operators is not yet implemented in frappe.db.query engine. Use db_query (frappe.get_list) instead.
  val = self.func(instance)
/usr/lib/python3.10/functools.py:981: UserWarning: The 'filters_config' hook used to add custom operators is not yet implemented in frappe.db.query engine. Use db_query (frappe.get_list) instead.
  val = self.func(instance)
/usr/lib/python3.10/functools.py:981: UserWarning: The 'filters_config' hook used to add custom operators is not yet implemented in frappe.db.query engine. Use db_query (frappe.get_list) instead.
  val = self.func(instance)
/home/admin123/frappe-bench/env/lib/python3.10/site-packages/botocore/httpsession.py:19: DeprecationWarning: 'urllib3.contrib.pyopenssl' module is deprecated and will be removed in a future release of urllib3 2.x. Read more in this issue: https://github.com/urllib3/urllib3/issues/2680
  from urllib3.contrib.pyopenssl import orig_util_SSLContext as SSLContext
/usr/lib/python3.10/functools.py:981: UserWarning: The 'filters_config' hook used to add custom operators is not yet implemented in frappe.db.query engine. Use db_query (frappe.get_list) instead.
  val = self.func(instance)
/usr/lib/python3.10/functools.py:981: UserWarning: The 'filters_config' hook used to add custom operators is not yet implemented in frappe.db.query engine. Use db_query (frappe.get_list) instead.
  val = self.func(instance)
/usr/lib/python3.10/functools.py:981: UserWarning: The 'filters_config' hook used to add custom operators is not yet implemented in frappe.db.query engine. Use db_query (frappe.get_list) instead.
  val = self.func(instance)
/usr/lib/python3.10/functools.py:981: UserWarning: The 'filters_config' hook used to add custom operators is not yet implemented in frappe.db.query engine. Use db_query (frappe.get_list) instead.
  val = self.func(instance)
/home/admin123/frappe-bench/env/lib/python3.10/site-packages/botocore/httpsession.py:19: DeprecationWarning: 'urllib3.contrib.pyopenssl' module is deprecated and will be removed in a future release of urllib3 2.x. Read more in this issue: https://github.com/urllib3/urllib3/issues/2680
  from urllib3.contrib.pyopenssl import orig_util_SSLContext as SSLContext
/usr/lib/python3.10/functools.py:981: UserWarning: The 'filters_config' hook used to add custom operators is not yet implemented in frappe.db.query engine. Use db_query (frappe.get_list) instead.
  val = self.func(instance)
/usr/lib/python3.10/functools.py:981: UserWarning: The 'filters_config' hook used to add custom operators is not yet implemented in frappe.db.query engine. Use db_query (frappe.get_list) instead.
  val = self.func(instance)
/usr/lib/python3.10/functools.py:981: UserWarning: The 'filters_config' hook used to add custom operators is not yet implemented in frappe.db.query engine. Use db_query (frappe.get_list) instead.
  val = self.func(instance)
/usr/lib/python3.10/functools.py:981: UserWarning: The 'filters_config' hook used to add custom operators is not yet implemented in frappe.db.query engine. Use db_query (frappe.get_list) instead.
  val = self.func(instance)
/home/admin123/frappe-bench/env/lib/python3.10/site-packages/botocore/httpsession.py:19: DeprecationWarning: 'urllib3.contrib.pyopenssl' module is deprecated and will be removed in a future release of urllib3 2.x. Read more in this issue: https://github.com/urllib3/urllib3/issues/2680
  from urllib3.contrib.pyopenssl import orig_util_SSLContext as SSLContext
/usr/lib/python3.10/functools.py:981: UserWarning: The 'filters_config' hook used to add custom operators is not yet implemented in frappe.db.query engine. Use db_query (frappe.get_list) instead.
  val = self.func(instance)
/usr/lib/python3.10/functools.py:981: UserWarning: The 'filters_config' hook used to add custom operators is not yet implemented in frappe.db.query engine. Use db_query (frappe.get_list) instead.
  val = self.func(instance)
/usr/lib/python3.10/functools.py:981: UserWarning: The 'filters_config' hook used to add custom operators is not yet implemented in frappe.db.query engine. Use db_query (frappe.get_list) instead.
  val = self.func(instance)
Exception in thread Thread-1:
Traceback (most recent call last):
  File "/usr/lib/python3.10/threading.py", line 1016, in _bootstrap_inner
    self.run()
  File "/home/admin123/frappe-bench/env/lib/python3.10/site-packages/redis/client.py", line 3718, in run
    pubsub.get_message(ignore_subscribe_messages=True,
  File "/home/admin123/frappe-bench/env/lib/python3.10/site-packages/redis/client.py", line 3617, in get_message
    response = self.parse_response(block=False, timeout=timeout)
  File "/home/admin123/frappe-bench/env/lib/python3.10/site-packages/redis/client.py", line 3503, in parse_response
    if not block and not conn.can_read(timeout=timeout):
  File "/home/admin123/frappe-bench/env/lib/python3.10/site-packages/redis/connection.py", line 734, in can_read
    return self._parser.can_read(timeout)
  File "/home/admin123/frappe-bench/env/lib/python3.10/site-packages/redis/connection.py", line 416, in can_read
    return self.read_from_socket(timeout=timeout,
  File "/home/admin123/frappe-bench/env/lib/python3.10/site-packages/redis/connection.py", line 429, in read_from_socket
    raise ConnectionError(SERVER_CLOSED_CONNECTION_ERROR)
redis.exceptions.ConnectionError: Connection closed by server.
fatal: No remote configured to list refs from.
fatal: No remote configured to list refs from.
fatal: No remote configured to list refs from.
fatal: No remote configured to list refs from.
fatal: No remote configured to list refs from.
2023-10-20 07:02:58,757 Traceback (most recent call last):
  File "/home/admin123/frappe-bench/apps/frappe/frappe/database/database.py", line 220, in sql
    self._cursor.execute(query, values)
  File "/home/admin123/frappe-bench/env/lib/python3.10/site-packages/pymysql/cursors.py", line 158, in execute
    result = self._query(query)
  File "/home/admin123/frappe-bench/env/lib/python3.10/site-packages/pymysql/cursors.py", line 325, in _query
    conn.query(q)
  File "/home/admin123/frappe-bench/env/lib/python3.10/site-packages/pymysql/connections.py", line 549, in query
    self._affected_rows = self._read_query_result(unbuffered=unbuffered)
  File "/home/admin123/frappe-bench/env/lib/python3.10/site-packages/pymysql/connections.py", line 779, in _read_query_result
    result.read()
  File "/home/admin123/frappe-bench/env/lib/python3.10/site-packages/pymysql/connections.py", line 1157, in read
    first_packet = self.connection._read_packet()
  File "/home/admin123/frappe-bench/env/lib/python3.10/site-packages/pymysql/connections.py", line 729, in _read_packet
    packet.raise_for_error()
  File "/home/admin123/frappe-bench/env/lib/python3.10/site-packages/pymysql/protocol.py", line 221, in raise_for_error
    err.raise_mysql_exception(self._data)
  File "/home/admin123/frappe-bench/env/lib/python3.10/site-packages/pymysql/err.py", line 143, in raise_mysql_exception
    raise errorclass(errno, errval)
pymysql.err.OperationalError: (1213, 'Deadlock found when trying to get lock; try restarting transaction')

The above exception was the direct cause of the following exception:

Traceback (most recent call last):
  File "/home/admin123/frappe-bench/env/lib/python3.10/site-packages/rq/worker.py", line 1075, in perform_job
    rv = job.perform()
  File "/home/admin123/frappe-bench/env/lib/python3.10/site-packages/rq/job.py", line 854, in perform
    self._result = self._execute()
  File "/home/admin123/frappe-bench/env/lib/python3.10/site-packages/rq/job.py", line 877, in _execute
    result = self.func(*self.args, **self.kwargs)
  File "/home/admin123/frappe-bench/apps/frappe/frappe/utils/background_jobs.py", line 189, in execute_job
    retval = method(**kwargs)
  File "/home/admin123/frappe-bench/apps/frappe/frappe/model/delete_doc.py", line 356, in delete_dynamic_links
    delete_references("Version", doctype, name, "ref_doctype", "docname")
  File "/home/admin123/frappe-bench/apps/frappe/frappe/model/delete_doc.py", line 377, in delete_references
    frappe.db.delete(
  File "/home/admin123/frappe-bench/apps/frappe/frappe/database/database.py", line 1259, in delete
    return query.run(**kwargs)
  File "/home/admin123/frappe-bench/apps/frappe/frappe/query_builder/utils.py", line 76, in execute_query
    return frappe.db.sql(query, params, *args, **kwargs)  # nosemgrep
  File "/home/admin123/frappe-bench/apps/frappe/frappe/database/database.py", line 226, in sql
    raise frappe.QueryDeadlockError(e) from e
frappe.exceptions.QueryDeadlockError: (1213, 'Deadlock found when trying to get lock; try restarting transaction')
Traceback (most recent call last):
  File "/home/admin123/frappe-bench/apps/frappe/frappe/database/database.py", line 220, in sql
    self._cursor.execute(query, values)
  File "/home/admin123/frappe-bench/env/lib/python3.10/site-packages/pymysql/cursors.py", line 158, in execute
    result = self._query(query)
  File "/home/admin123/frappe-bench/env/lib/python3.10/site-packages/pymysql/cursors.py", line 325, in _query
    conn.query(q)
  File "/home/admin123/frappe-bench/env/lib/python3.10/site-packages/pymysql/connections.py", line 549, in query
    self._affected_rows = self._read_query_result(unbuffered=unbuffered)
  File "/home/admin123/frappe-bench/env/lib/python3.10/site-packages/pymysql/connections.py", line 779, in _read_query_result
    result.read()
  File "/home/admin123/frappe-bench/env/lib/python3.10/site-packages/pymysql/connections.py", line 1157, in read
    first_packet = self.connection._read_packet()
  File "/home/admin123/frappe-bench/env/lib/python3.10/site-packages/pymysql/connections.py", line 729, in _read_packet
    packet.raise_for_error()
  File "/home/admin123/frappe-bench/env/lib/python3.10/site-packages/pymysql/protocol.py", line 221, in raise_for_error
    err.raise_mysql_exception(self._data)
  File "/home/admin123/frappe-bench/env/lib/python3.10/site-packages/pymysql/err.py", line 143, in raise_mysql_exception
    raise errorclass(errno, errval)
pymysql.err.OperationalError: (1213, 'Deadlock found when trying to get lock; try restarting transaction')

The above exception was the direct cause of the following exception:

Traceback (most recent call last):
  File "/home/admin123/frappe-bench/env/lib/python3.10/site-packages/rq/worker.py", line 1075, in perform_job
    rv = job.perform()
  File "/home/admin123/frappe-bench/env/lib/python3.10/site-packages/rq/job.py", line 854, in perform
    self._result = self._execute()
  File "/home/admin123/frappe-bench/env/lib/python3.10/site-packages/rq/job.py", line 877, in _execute
    result = self.func(*self.args, **self.kwargs)
  File "/home/admin123/frappe-bench/apps/frappe/frappe/utils/background_jobs.py", line 189, in execute_job
    retval = method(**kwargs)
  File "/home/admin123/frappe-bench/apps/frappe/frappe/model/delete_doc.py", line 356, in delete_dynamic_links
    delete_references("Version", doctype, name, "ref_doctype", "docname")
  File "/home/admin123/frappe-bench/apps/frappe/frappe/model/delete_doc.py", line 377, in delete_references
    frappe.db.delete(
  File "/home/admin123/frappe-bench/apps/frappe/frappe/database/database.py", line 1259, in delete
    return query.run(**kwargs)
  File "/home/admin123/frappe-bench/apps/frappe/frappe/query_builder/utils.py", line 76, in execute_query
    return frappe.db.sql(query, params, *args, **kwargs)  # nosemgrep
  File "/home/admin123/frappe-bench/apps/frappe/frappe/database/database.py", line 226, in sql
    raise frappe.QueryDeadlockError(e) from e
frappe.exceptions.QueryDeadlockError: (1213, 'Deadlock found when trying to get lock; try restarting transaction')
2023-10-31 07:12:55,560 Traceback (most recent call last):
  File "/home/admin123/frappe-bench/apps/frappe/frappe/email/smtp.py", line 114, in session
    res = _session.login(str(self.login or ""), str(self.password or ""))
  File "/usr/lib/python3.10/smtplib.py", line 750, in login
    raise last_exception
  File "/usr/lib/python3.10/smtplib.py", line 739, in login
    (code, resp) = self.auth(
  File "/usr/lib/python3.10/smtplib.py", line 662, in auth
    raise SMTPAuthenticationError(code, resp)
smtplib.SMTPAuthenticationError: (535, b'5.7.8 Username and Password not accepted. Learn more at\n5.7.8  https://support.google.com/mail/?p=BadCredentials e9-20020a4aaac9000000b0057e88d4f8aesm187219oon.27 - gsmtp')

During handling of the above exception, another exception occurred:

Traceback (most recent call last):
  File "/home/admin123/frappe-bench/env/lib/python3.10/site-packages/rq/worker.py", line 1075, in perform_job
    rv = job.perform()
  File "/home/admin123/frappe-bench/env/lib/python3.10/site-packages/rq/job.py", line 854, in perform
    self._result = self._execute()
  File "/home/admin123/frappe-bench/env/lib/python3.10/site-packages/rq/job.py", line 877, in _execute
    result = self.func(*self.args, **self.kwargs)
  File "/home/admin123/frappe-bench/apps/frappe/frappe/utils/background_jobs.py", line 189, in execute_job
    retval = method(**kwargs)
  File "/home/admin123/frappe-bench/apps/frappe/frappe/email/doctype/email_queue/email_queue.py", line 185, in send_mail
    record.send(is_background_task=is_background_task, smtp_server_instance=smtp_server_instance)
  File "/home/admin123/frappe-bench/apps/frappe/frappe/email/doctype/email_queue/email_queue.py", line 142, in send
    ctx.smtp_session.sendmail(from_addr=self.sender, to_addrs=recipient.recipient, msg=message)
  File "/home/admin123/frappe-bench/apps/frappe/frappe/email/doctype/email_queue/email_queue.py", line 257, in smtp_session
    return self.smtp_server.session
  File "/home/admin123/frappe-bench/apps/frappe/frappe/email/smtp.py", line 124, in session
    self.throw_invalid_credentials_exception()
  File "/home/admin123/frappe-bench/apps/frappe/frappe/email/smtp.py", line 143, in throw_invalid_credentials_exception
    frappe.throw(
  File "/home/admin123/frappe-bench/apps/frappe/frappe/__init__.py", line 528, in throw
    msgprint(
  File "/home/admin123/frappe-bench/apps/frappe/frappe/__init__.py", line 496, in msgprint
    _raise_exception()
  File "/home/admin123/frappe-bench/apps/frappe/frappe/__init__.py", line 445, in _raise_exception
    raise raise_exception(msg)
frappe.email.smtp.InvalidEmailCredentials: Please check your email login credentials.
Traceback (most recent call last):
  File "/home/admin123/frappe-bench/apps/frappe/frappe/email/smtp.py", line 114, in session
    res = _session.login(str(self.login or ""), str(self.password or ""))
  File "/usr/lib/python3.10/smtplib.py", line 750, in login
    raise last_exception
  File "/usr/lib/python3.10/smtplib.py", line 739, in login
    (code, resp) = self.auth(
  File "/usr/lib/python3.10/smtplib.py", line 662, in auth
    raise SMTPAuthenticationError(code, resp)
smtplib.SMTPAuthenticationError: (535, b'5.7.8 Username and Password not accepted. Learn more at\n5.7.8  https://support.google.com/mail/?p=BadCredentials e9-20020a4aaac9000000b0057e88d4f8aesm187219oon.27 - gsmtp')

During handling of the above exception, another exception occurred:

Traceback (most recent call last):
  File "/home/admin123/frappe-bench/env/lib/python3.10/site-packages/rq/worker.py", line 1075, in perform_job
    rv = job.perform()
  File "/home/admin123/frappe-bench/env/lib/python3.10/site-packages/rq/job.py", line 854, in perform
    self._result = self._execute()
  File "/home/admin123/frappe-bench/env/lib/python3.10/site-packages/rq/job.py", line 877, in _execute
    result = self.func(*self.args, **self.kwargs)
  File "/home/admin123/frappe-bench/apps/frappe/frappe/utils/background_jobs.py", line 189, in execute_job
    retval = method(**kwargs)
  File "/home/admin123/frappe-bench/apps/frappe/frappe/email/doctype/email_queue/email_queue.py", line 185, in send_mail
    record.send(is_background_task=is_background_task, smtp_server_instance=smtp_server_instance)
  File "/home/admin123/frappe-bench/apps/frappe/frappe/email/doctype/email_queue/email_queue.py", line 142, in send
    ctx.smtp_session.sendmail(from_addr=self.sender, to_addrs=recipient.recipient, msg=message)
  File "/home/admin123/frappe-bench/apps/frappe/frappe/email/doctype/email_queue/email_queue.py", line 257, in smtp_session
    return self.smtp_server.session
  File "/home/admin123/frappe-bench/apps/frappe/frappe/email/smtp.py", line 124, in session
    self.throw_invalid_credentials_exception()
  File "/home/admin123/frappe-bench/apps/frappe/frappe/email/smtp.py", line 143, in throw_invalid_credentials_exception
    frappe.throw(
  File "/home/admin123/frappe-bench/apps/frappe/frappe/__init__.py", line 528, in throw
    msgprint(
  File "/home/admin123/frappe-bench/apps/frappe/frappe/__init__.py", line 496, in msgprint
    _raise_exception()
  File "/home/admin123/frappe-bench/apps/frappe/frappe/__init__.py", line 445, in _raise_exception
    raise raise_exception(msg)
frappe.email.smtp.InvalidEmailCredentials: Please check your email login credentials.
2023-10-31 07:16:57,378 Traceback (most recent call last):
  File "/home/admin123/frappe-bench/apps/frappe/frappe/email/smtp.py", line 114, in session
    res = _session.login(str(self.login or ""), str(self.password or ""))
  File "/usr/lib/python3.10/smtplib.py", line 750, in login
    raise last_exception
  File "/usr/lib/python3.10/smtplib.py", line 739, in login
    (code, resp) = self.auth(
  File "/usr/lib/python3.10/smtplib.py", line 662, in auth
    raise SMTPAuthenticationError(code, resp)
smtplib.SMTPAuthenticationError: (535, b'5.7.8 Username and Password not accepted. Learn more at\n5.7.8  https://support.google.com/mail/?p=BadCredentials dk17-20020a4aee91000000b00581ea8fa1ebsm210353oob.26 - gsmtp')

During handling of the above exception, another exception occurred:

Traceback (most recent call last):
  File "/home/admin123/frappe-bench/env/lib/python3.10/site-packages/rq/worker.py", line 1075, in perform_job
    rv = job.perform()
  File "/home/admin123/frappe-bench/env/lib/python3.10/site-packages/rq/job.py", line 854, in perform
    self._result = self._execute()
  File "/home/admin123/frappe-bench/env/lib/python3.10/site-packages/rq/job.py", line 877, in _execute
    result = self.func(*self.args, **self.kwargs)
  File "/home/admin123/frappe-bench/apps/frappe/frappe/utils/background_jobs.py", line 189, in execute_job
    retval = method(**kwargs)
  File "/home/admin123/frappe-bench/apps/frappe/frappe/email/doctype/email_queue/email_queue.py", line 185, in send_mail
    record.send(is_background_task=is_background_task, smtp_server_instance=smtp_server_instance)
  File "/home/admin123/frappe-bench/apps/frappe/frappe/email/doctype/email_queue/email_queue.py", line 142, in send
    ctx.smtp_session.sendmail(from_addr=self.sender, to_addrs=recipient.recipient, msg=message)
  File "/home/admin123/frappe-bench/apps/frappe/frappe/email/doctype/email_queue/email_queue.py", line 257, in smtp_session
    return self.smtp_server.session
  File "/home/admin123/frappe-bench/apps/frappe/frappe/email/smtp.py", line 124, in session
    self.throw_invalid_credentials_exception()
  File "/home/admin123/frappe-bench/apps/frappe/frappe/email/smtp.py", line 143, in throw_invalid_credentials_exception
    frappe.throw(
  File "/home/admin123/frappe-bench/apps/frappe/frappe/__init__.py", line 528, in throw
    msgprint(
  File "/home/admin123/frappe-bench/apps/frappe/frappe/__init__.py", line 496, in msgprint
    _raise_exception()
  File "/home/admin123/frappe-bench/apps/frappe/frappe/__init__.py", line 445, in _raise_exception
    raise raise_exception(msg)
frappe.email.smtp.InvalidEmailCredentials: Please check your email login credentials.
Traceback (most recent call last):
  File "/home/admin123/frappe-bench/apps/frappe/frappe/email/smtp.py", line 114, in session
    res = _session.login(str(self.login or ""), str(self.password or ""))
  File "/usr/lib/python3.10/smtplib.py", line 750, in login
    raise last_exception
  File "/usr/lib/python3.10/smtplib.py", line 739, in login
    (code, resp) = self.auth(
  File "/usr/lib/python3.10/smtplib.py", line 662, in auth
    raise SMTPAuthenticationError(code, resp)
smtplib.SMTPAuthenticationError: (535, b'5.7.8 Username and Password not accepted. Learn more at\n5.7.8  https://support.google.com/mail/?p=BadCredentials dk17-20020a4aee91000000b00581ea8fa1ebsm210353oob.26 - gsmtp')

During handling of the above exception, another exception occurred:

Traceback (most recent call last):
  File "/home/admin123/frappe-bench/env/lib/python3.10/site-packages/rq/worker.py", line 1075, in perform_job
    rv = job.perform()
  File "/home/admin123/frappe-bench/env/lib/python3.10/site-packages/rq/job.py", line 854, in perform
    self._result = self._execute()
  File "/home/admin123/frappe-bench/env/lib/python3.10/site-packages/rq/job.py", line 877, in _execute
    result = self.func(*self.args, **self.kwargs)
  File "/home/admin123/frappe-bench/apps/frappe/frappe/utils/background_jobs.py", line 189, in execute_job
    retval = method(**kwargs)
  File "/home/admin123/frappe-bench/apps/frappe/frappe/email/doctype/email_queue/email_queue.py", line 185, in send_mail
    record.send(is_background_task=is_background_task, smtp_server_instance=smtp_server_instance)
  File "/home/admin123/frappe-bench/apps/frappe/frappe/email/doctype/email_queue/email_queue.py", line 142, in send
    ctx.smtp_session.sendmail(from_addr=self.sender, to_addrs=recipient.recipient, msg=message)
  File "/home/admin123/frappe-bench/apps/frappe/frappe/email/doctype/email_queue/email_queue.py", line 257, in smtp_session
    return self.smtp_server.session
  File "/home/admin123/frappe-bench/apps/frappe/frappe/email/smtp.py", line 124, in session
    self.throw_invalid_credentials_exception()
  File "/home/admin123/frappe-bench/apps/frappe/frappe/email/smtp.py", line 143, in throw_invalid_credentials_exception
    frappe.throw(
  File "/home/admin123/frappe-bench/apps/frappe/frappe/__init__.py", line 528, in throw
    msgprint(
  File "/home/admin123/frappe-bench/apps/frappe/frappe/__init__.py", line 496, in msgprint
    _raise_exception()
  File "/home/admin123/frappe-bench/apps/frappe/frappe/__init__.py", line 445, in _raise_exception
    raise raise_exception(msg)
frappe.email.smtp.InvalidEmailCredentials: Please check your email login credentials.
2023-10-31 07:20:58,169 Traceback (most recent call last):
  File "/home/admin123/frappe-bench/apps/frappe/frappe/email/smtp.py", line 114, in session
    res = _session.login(str(self.login or ""), str(self.password or ""))
  File "/usr/lib/python3.10/smtplib.py", line 750, in login
    raise last_exception
  File "/usr/lib/python3.10/smtplib.py", line 739, in login
    (code, resp) = self.auth(
  File "/usr/lib/python3.10/smtplib.py", line 662, in auth
    raise SMTPAuthenticationError(code, resp)
smtplib.SMTPAuthenticationError: (535, b'5.7.8 Username and Password not accepted. Learn more at\n5.7.8  https://support.google.com/mail/?p=BadCredentials p1-20020a056870868100b001e5c7cc54d3sm251111oam.55 - gsmtp')

During handling of the above exception, another exception occurred:

Traceback (most recent call last):
  File "/home/admin123/frappe-bench/env/lib/python3.10/site-packages/rq/worker.py", line 1075, in perform_job
    rv = job.perform()
  File "/home/admin123/frappe-bench/env/lib/python3.10/site-packages/rq/job.py", line 854, in perform
    self._result = self._execute()
  File "/home/admin123/frappe-bench/env/lib/python3.10/site-packages/rq/job.py", line 877, in _execute
    result = self.func(*self.args, **self.kwargs)
  File "/home/admin123/frappe-bench/apps/frappe/frappe/utils/background_jobs.py", line 189, in execute_job
    retval = method(**kwargs)
  File "/home/admin123/frappe-bench/apps/frappe/frappe/email/doctype/email_queue/email_queue.py", line 185, in send_mail
    record.send(is_background_task=is_background_task, smtp_server_instance=smtp_server_instance)
  File "/home/admin123/frappe-bench/apps/frappe/frappe/email/doctype/email_queue/email_queue.py", line 142, in send
    ctx.smtp_session.sendmail(from_addr=self.sender, to_addrs=recipient.recipient, msg=message)
  File "/home/admin123/frappe-bench/apps/frappe/frappe/email/doctype/email_queue/email_queue.py", line 257, in smtp_session
    return self.smtp_server.session
  File "/home/admin123/frappe-bench/apps/frappe/frappe/email/smtp.py", line 124, in session
    self.throw_invalid_credentials_exception()
  File "/home/admin123/frappe-bench/apps/frappe/frappe/email/smtp.py", line 143, in throw_invalid_credentials_exception
    frappe.throw(
  File "/home/admin123/frappe-bench/apps/frappe/frappe/__init__.py", line 528, in throw
    msgprint(
  File "/home/admin123/frappe-bench/apps/frappe/frappe/__init__.py", line 496, in msgprint
    _raise_exception()
  File "/home/admin123/frappe-bench/apps/frappe/frappe/__init__.py", line 445, in _raise_exception
    raise raise_exception(msg)
frappe.email.smtp.InvalidEmailCredentials: Please check your email login credentials.
Traceback (most recent call last):
  File "/home/admin123/frappe-bench/apps/frappe/frappe/email/smtp.py", line 114, in session
    res = _session.login(str(self.login or ""), str(self.password or ""))
  File "/usr/lib/python3.10/smtplib.py", line 750, in login
    raise last_exception
  File "/usr/lib/python3.10/smtplib.py", line 739, in login
    (code, resp) = self.auth(
  File "/usr/lib/python3.10/smtplib.py", line 662, in auth
    raise SMTPAuthenticationError(code, resp)
smtplib.SMTPAuthenticationError: (535, b'5.7.8 Username and Password not accepted. Learn more at\n5.7.8  https://support.google.com/mail/?p=BadCredentials p1-20020a056870868100b001e5c7cc54d3sm251111oam.55 - gsmtp')

During handling of the above exception, another exception occurred:

Traceback (most recent call last):
  File "/home/admin123/frappe-bench/env/lib/python3.10/site-packages/rq/worker.py", line 1075, in perform_job
    rv = job.perform()
  File "/home/admin123/frappe-bench/env/lib/python3.10/site-packages/rq/job.py", line 854, in perform
    self._result = self._execute()
  File "/home/admin123/frappe-bench/env/lib/python3.10/site-packages/rq/job.py", line 877, in _execute
    result = self.func(*self.args, **self.kwargs)
  File "/home/admin123/frappe-bench/apps/frappe/frappe/utils/background_jobs.py", line 189, in execute_job
    retval = method(**kwargs)
  File "/home/admin123/frappe-bench/apps/frappe/frappe/email/doctype/email_queue/email_queue.py", line 185, in send_mail
    record.send(is_background_task=is_background_task, smtp_server_instance=smtp_server_instance)
  File "/home/admin123/frappe-bench/apps/frappe/frappe/email/doctype/email_queue/email_queue.py", line 142, in send
    ctx.smtp_session.sendmail(from_addr=self.sender, to_addrs=recipient.recipient, msg=message)
  File "/home/admin123/frappe-bench/apps/frappe/frappe/email/doctype/email_queue/email_queue.py", line 257, in smtp_session
    return self.smtp_server.session
  File "/home/admin123/frappe-bench/apps/frappe/frappe/email/smtp.py", line 124, in session
    self.throw_invalid_credentials_exception()
  File "/home/admin123/frappe-bench/apps/frappe/frappe/email/smtp.py", line 143, in throw_invalid_credentials_exception
    frappe.throw(
  File "/home/admin123/frappe-bench/apps/frappe/frappe/__init__.py", line 528, in throw
    msgprint(
  File "/home/admin123/frappe-bench/apps/frappe/frappe/__init__.py", line 496, in msgprint
    _raise_exception()
  File "/home/admin123/frappe-bench/apps/frappe/frappe/__init__.py", line 445, in _raise_exception
    raise raise_exception(msg)
frappe.email.smtp.InvalidEmailCredentials: Please check your email login credentials.
Exception in thread Thread-1:
Traceback (most recent call last):
  File "/usr/lib/python3.10/threading.py", line 1016, in _bootstrap_inner
    self.run()
  File "/home/admin123/frappe-bench/env/lib/python3.10/site-packages/redis/client.py", line 3718, in run
Exception in thread Thread-1:
Traceback (most recent call last):
  File "/usr/lib/python3.10/threading.py", line 1016, in _bootstrap_inner
    self.run()
  File "/home/admin123/frappe-bench/env/lib/python3.10/site-packages/redis/client.py", line 3718, in run
    pubsub.get_message(ignore_subscribe_messages=True,
  File "/home/admin123/frappe-bench/env/lib/python3.10/site-packages/redis/client.py", line 3617, in get_message
    pubsub.get_message(ignore_subscribe_messages=True,
  File "/home/admin123/frappe-bench/env/lib/python3.10/site-packages/redis/client.py", line 3617, in get_message
    response = self.parse_response(block=False, timeout=timeout)
  File "/home/admin123/frappe-bench/env/lib/python3.10/site-packages/redis/client.py", line 3503, in parse_response
    if not block and not conn.can_read(timeout=timeout):
  File "/home/admin123/frappe-bench/env/lib/python3.10/site-packages/redis/connection.py", line 734, in can_read
    return self._parser.can_read(timeout)
  File "/home/admin123/frappe-bench/env/lib/python3.10/site-packages/redis/connection.py", line 416, in can_read
    return self.read_from_socket(timeout=timeout,
  File "/home/admin123/frappe-bench/env/lib/python3.10/site-packages/redis/connection.py", line 429, in read_from_socket
    raise ConnectionError(SERVER_CLOSED_CONNECTION_ERROR)
redis.exceptions.ConnectionError: Connection closed by server.
    response = self.parse_response(block=False, timeout=timeout)
  File "/home/admin123/frappe-bench/env/lib/python3.10/site-packages/redis/client.py", line 3503, in parse_response
    if not block and not conn.can_read(timeout=timeout):
  File "/home/admin123/frappe-bench/env/lib/python3.10/site-packages/redis/connection.py", line 734, in can_read
    return self._parser.can_read(timeout)
  File "/home/admin123/frappe-bench/env/lib/python3.10/site-packages/redis/connection.py", line 416, in can_read
    return self.read_from_socket(timeout=timeout,
  File "/home/admin123/frappe-bench/env/lib/python3.10/site-packages/redis/connection.py", line 429, in read_from_socket
    raise ConnectionError(SERVER_CLOSED_CONNECTION_ERROR)
redis.exceptions.ConnectionError: Connection closed by server.
Exception in thread Thread-1:
Traceback (most recent call last):
  File "/usr/lib/python3.10/threading.py", line 1016, in _bootstrap_inner
Exception in thread Thread-1:
Traceback (most recent call last):
  File "/usr/lib/python3.10/threading.py", line 1016, in _bootstrap_inner
    self.run()
  File "/home/admin123/frappe-bench/env/lib/python3.10/site-packages/redis/client.py", line 3718, in run
    pubsub.get_message(ignore_subscribe_messages=True,
  File "/home/admin123/frappe-bench/env/lib/python3.10/site-packages/redis/client.py", line 3617, in get_message
2023-11-21 13:52:29,304 Could not connect to Redis instance: Connection closed by server. Retrying in 1 seconds...
    self.run()
  File "/home/admin123/frappe-bench/env/lib/python3.10/site-packages/redis/client.py", line 3718, in run
2023-11-21 13:52:29,305 Could not connect to Redis instance: Connection closed by server. Retrying in 1 seconds...
Exception in thread Thread-1:
Traceback (most recent call last):
  File "/usr/lib/python3.10/threading.py", line 1016, in _bootstrap_inner
    self.run()
  File "/home/admin123/frappe-bench/env/lib/python3.10/site-packages/redis/client.py", line 3718, in run
    response = self.parse_response(block=False, timeout=timeout)
  File "/home/admin123/frappe-bench/env/lib/python3.10/site-packages/redis/client.py", line 3503, in parse_response
2023-11-21 13:52:29,305 Could not connect to Redis instance: Connection closed by server. Retrying in 1 seconds...
    if not block and not conn.can_read(timeout=timeout):
  File "/home/admin123/frappe-bench/env/lib/python3.10/site-packages/redis/connection.py", line 734, in can_read
    return self._parser.can_read(timeout)
  File "/home/admin123/frappe-bench/env/lib/python3.10/site-packages/redis/connection.py", line 416, in can_read
    return self.read_from_socket(timeout=timeout,
  File "/home/admin123/frappe-bench/env/lib/python3.10/site-packages/redis/connection.py", line 429, in read_from_socket
    raise ConnectionError(SERVER_CLOSED_CONNECTION_ERROR)
redis.exceptions.ConnectionError: Connection closed by server.
    pubsub.get_message(ignore_subscribe_messages=True,
  File "/home/admin123/frappe-bench/env/lib/python3.10/site-packages/redis/client.py", line 3617, in get_message
    response = self.parse_response(block=False, timeout=timeout)
  File "/home/admin123/frappe-bench/env/lib/python3.10/site-packages/redis/client.py", line 3503, in parse_response
    if not block and not conn.can_read(timeout=timeout):
  File "/home/admin123/frappe-bench/env/lib/python3.10/site-packages/redis/connection.py", line 734, in can_read
    return self._parser.can_read(timeout)
  File "/home/admin123/frappe-bench/env/lib/python3.10/site-packages/redis/connection.py", line 416, in can_read
    return self.read_from_socket(timeout=timeout,
  File "/home/admin123/frappe-bench/env/lib/python3.10/site-packages/redis/connection.py", line 429, in read_from_socket
    raise ConnectionError(SERVER_CLOSED_CONNECTION_ERROR)
redis.exceptions.ConnectionError: Connection closed by server.
    pubsub.get_message(ignore_subscribe_messages=True,
  File "/home/admin123/frappe-bench/env/lib/python3.10/site-packages/redis/client.py", line 3617, in get_message
    response = self.parse_response(block=False, timeout=timeout)
  File "/home/admin123/frappe-bench/env/lib/python3.10/site-packages/redis/client.py", line 3503, in parse_response
    if not block and not conn.can_read(timeout=timeout):
  File "/home/admin123/frappe-bench/env/lib/python3.10/site-packages/redis/connection.py", line 734, in can_read
    return self._parser.can_read(timeout)
  File "/home/admin123/frappe-bench/env/lib/python3.10/site-packages/redis/connection.py", line 416, in can_read
    return self.read_from_socket(timeout=timeout,
  File "/home/admin123/frappe-bench/env/lib/python3.10/site-packages/redis/connection.py", line 429, in read_from_socket
    raise ConnectionError(SERVER_CLOSED_CONNECTION_ERROR)
redis.exceptions.ConnectionError: Connection closed by server.
Exception in thread Thread-1:
Traceback (most recent call last):
  File "/usr/lib/python3.10/threading.py", line 1016, in _bootstrap_inner
    self.run()
  File "/home/admin123/frappe-bench/env/lib/python3.10/site-packages/redis/client.py", line 3718, in run
    pubsub.get_message(ignore_subscribe_messages=True,
  File "/home/admin123/frappe-bench/env/lib/python3.10/site-packages/redis/client.py", line 3617, in get_message
    response = self.parse_response(block=False, timeout=timeout)
  File "/home/admin123/frappe-bench/env/lib/python3.10/site-packages/redis/client.py", line 3503, in parse_response
    if not block and not conn.can_read(timeout=timeout):
  File "/home/admin123/frappe-bench/env/lib/python3.10/site-packages/redis/connection.py", line 734, in can_read
    return self._parser.can_read(timeout)
  File "/home/admin123/frappe-bench/env/lib/python3.10/site-packages/redis/connection.py", line 416, in can_read
    return self.read_from_socket(timeout=timeout,
  File "/home/admin123/frappe-bench/env/lib/python3.10/site-packages/redis/connection.py", line 429, in read_from_socket
    raise ConnectionError(SERVER_CLOSED_CONNECTION_ERROR)
redis.exceptions.ConnectionError: Connection closed by server.
Exception in thread Thread-1:
Traceback (most recent call last):
  File "/usr/lib/python3.10/threading.py", line 1016, in _bootstrap_inner
    self.run()
  File "/home/admin123/frappe-bench/env/lib/python3.10/site-packages/redis/client.py", line 3718, in run
    pubsub.get_message(ignore_subscribe_messages=True,
  File "/home/admin123/frappe-bench/env/lib/python3.10/site-packages/redis/client.py", line 3617, in get_message
    response = self.parse_response(block=False, timeout=timeout)
  File "/home/admin123/frappe-bench/env/lib/python3.10/site-packages/redis/client.py", line 3503, in parse_response
    if not block and not conn.can_read(timeout=timeout):
  File "/home/admin123/frappe-bench/env/lib/python3.10/site-packages/redis/connection.py", line 734, in can_read
    return self._parser.can_read(timeout)
  File "/home/admin123/frappe-bench/env/lib/python3.10/site-packages/redis/connection.py", line 416, in can_read
    return self.read_from_socket(timeout=timeout,
  File "/home/admin123/frappe-bench/env/lib/python3.10/site-packages/redis/connection.py", line 429, in read_from_socket
    raise ConnectionError(SERVER_CLOSED_CONNECTION_ERROR)
redis.exceptions.ConnectionError: Connection closed by server.
Exception in thread Thread-1:
Traceback (most recent call last):
  File "/usr/lib/python3.10/threading.py", line 1016, in _bootstrap_inner
    self.run()
  File "/home/admin123/frappe-bench/env/lib/python3.10/site-packages/redis/client.py", line 3718, in run
    pubsub.get_message(ignore_subscribe_messages=True,
  File "/home/admin123/frappe-bench/env/lib/python3.10/site-packages/redis/client.py", line 3617, in get_message
    response = self.parse_response(block=False, timeout=timeout)
  File "/home/admin123/frappe-bench/env/lib/python3.10/site-packages/redis/client.py", line 3503, in parse_response
    if not block and not conn.can_read(timeout=timeout):
  File "/home/admin123/frappe-bench/env/lib/python3.10/site-packages/redis/connection.py", line 734, in can_read
    return self._parser.can_read(timeout)
  File "/home/admin123/frappe-bench/env/lib/python3.10/site-packages/redis/connection.py", line 416, in can_read
    return self.read_from_socket(timeout=timeout,
  File "/home/admin123/frappe-bench/env/lib/python3.10/site-packages/redis/connection.py", line 429, in read_from_socket
    raise ConnectionError(SERVER_CLOSED_CONNECTION_ERROR)
redis.exceptions.ConnectionError: Connection closed by server.
Traceback (most recent call last):
  File "/home/admin123/frappe-bench/env/lib/python3.10/site-packages/redis/connection.py", line 559, in connect
    sock = self._connect()
  File "/home/admin123/frappe-bench/env/lib/python3.10/site-packages/redis/connection.py", line 615, in _connect
    raise err
  File "/home/admin123/frappe-bench/env/lib/python3.10/site-packages/redis/connection.py", line 603, in _connect
    sock.connect(socket_address)
ConnectionRefusedError: [Errno 111] Connection refused

During handling of the above exception, another exception occurred:

Traceback (most recent call last):
  File "/home/admin123/frappe-bench/env/lib/python3.10/site-packages/tenacity/__init__.py", line 407, in __call__
    result = fn(*args, **kwargs)
  File "/home/admin123/frappe-bench/apps/frappe/frappe/utils/background_jobs.py", line 388, in get_redis_conn
    _redis_queue_conn = RedisQueue.get_connection()
  File "/home/admin123/frappe-bench/apps/frappe/frappe/utils/redis_queue.py", line 24, in get_connection
    conn.ping()
  File "/home/admin123/frappe-bench/env/lib/python3.10/site-packages/redis/client.py", line 1378, in ping
    return self.execute_command('PING')
  File "/home/admin123/frappe-bench/env/lib/python3.10/site-packages/redis/client.py", line 898, in execute_command
    conn = self.connection or pool.get_connection(command_name, **options)
  File "/home/admin123/frappe-bench/env/lib/python3.10/site-packages/redis/connection.py", line 1192, in get_connection
    connection.connect()
  File "/home/admin123/frappe-bench/env/lib/python3.10/site-packages/redis/connection.py", line 563, in connect
    raise ConnectionError(self._error_message(e))
redis.exceptions.ConnectionError: Error 111 connecting to localhost:11000. Connection refused.

The above exception was the direct cause of the following exception:

Traceback (most recent call last):
  File "/usr/lib/python3.10/runpy.py", line 196, in _run_module_as_main
    return _run_code(code, main_globals, None,
  File "/usr/lib/python3.10/runpy.py", line 86, in _run_code
    exec(code, run_globals)
  File "/home/admin123/frappe-bench/apps/frappe/frappe/utils/bench_helper.py", line 109, in <module>
    main()
  File "/home/admin123/frappe-bench/apps/frappe/frappe/utils/bench_helper.py", line 18, in main
    click.Group(commands=commands)(prog_name="bench")
  File "/home/admin123/frappe-bench/env/lib/python3.10/site-packages/click/core.py", line 829, in __call__
    return self.main(*args, **kwargs)
  File "/home/admin123/frappe-bench/env/lib/python3.10/site-packages/click/core.py", line 782, in main
    rv = self.invoke(ctx)
  File "/home/admin123/frappe-bench/env/lib/python3.10/site-packages/click/core.py", line 1259, in invoke
    return _process_result(sub_ctx.command.invoke(sub_ctx))
  File "/home/admin123/frappe-bench/env/lib/python3.10/site-packages/click/core.py", line 1259, in invoke
    return _process_result(sub_ctx.command.invoke(sub_ctx))
  File "/home/admin123/frappe-bench/env/lib/python3.10/site-packages/click/core.py", line 1066, in invoke
    return ctx.invoke(self.callback, **ctx.params)
  File "/home/admin123/frappe-bench/env/lib/python3.10/site-packages/click/core.py", line 610, in invoke
    return callback(*args, **kwargs)
  File "/home/admin123/frappe-bench/apps/frappe/frappe/commands/scheduler.py", line 206, in start_worker
    start_worker(
  File "/home/admin123/frappe-bench/apps/frappe/frappe/utils/background_jobs.py", line 247, in start_worker
    redis_connection = get_redis_conn(username=rq_username, password=rq_password)
  File "/home/admin123/frappe-bench/env/lib/python3.10/site-packages/tenacity/__init__.py", line 324, in wrapped_f
    return self(f, *args, **kw)
  File "/home/admin123/frappe-bench/env/lib/python3.10/site-packages/tenacity/__init__.py", line 404, in __call__
    do = self.iter(retry_state=retry_state)
  File "/home/admin123/frappe-bench/env/lib/python3.10/site-packages/tenacity/__init__.py", line 361, in iter
    raise retry_exc from fut.exception()
tenacity.RetryError: RetryError[<Future at 0x7f6a79eb5a50 state=finished raised ConnectionError>]
Traceback (most recent call last):
  File "/home/admin123/frappe-bench/env/lib/python3.10/site-packages/redis/connection.py", line 559, in connect
    sock = self._connect()
  File "/home/admin123/frappe-bench/env/lib/python3.10/site-packages/redis/connection.py", line 615, in _connect
    raise err
  File "/home/admin123/frappe-bench/env/lib/python3.10/site-packages/redis/connection.py", line 603, in _connect
    sock.connect(socket_address)
ConnectionRefusedError: [Errno 111] Connection refused

During handling of the above exception, another exception occurred:

Traceback (most recent call last):
  File "/home/admin123/frappe-bench/env/lib/python3.10/site-packages/tenacity/__init__.py", line 407, in __call__
    result = fn(*args, **kwargs)
  File "/home/admin123/frappe-bench/apps/frappe/frappe/utils/background_jobs.py", line 388, in get_redis_conn
    _redis_queue_conn = RedisQueue.get_connection()
  File "/home/admin123/frappe-bench/apps/frappe/frappe/utils/redis_queue.py", line 24, in get_connection
    conn.ping()
  File "/home/admin123/frappe-bench/env/lib/python3.10/site-packages/redis/client.py", line 1378, in ping
    return self.execute_command('PING')
  File "/home/admin123/frappe-bench/env/lib/python3.10/site-packages/redis/client.py", line 898, in execute_command
    conn = self.connection or pool.get_connection(command_name, **options)
  File "/home/admin123/frappe-bench/env/lib/python3.10/site-packages/redis/connection.py", line 1192, in get_connection
    connection.connect()
  File "/home/admin123/frappe-bench/env/lib/python3.10/site-packages/redis/connection.py", line 563, in connect
    raise ConnectionError(self._error_message(e))
redis.exceptions.ConnectionError: Error 111 connecting to localhost:11000. Connection refused.

The above exception was the direct cause of the following exception:

Traceback (most recent call last):
  File "/usr/lib/python3.10/runpy.py", line 196, in _run_module_as_main
    return _run_code(code, main_globals, None,
  File "/usr/lib/python3.10/runpy.py", line 86, in _run_code
    exec(code, run_globals)
  File "/home/admin123/frappe-bench/apps/frappe/frappe/utils/bench_helper.py", line 109, in <module>
    main()
  File "/home/admin123/frappe-bench/apps/frappe/frappe/utils/bench_helper.py", line 18, in main
    click.Group(commands=commands)(prog_name="bench")
  File "/home/admin123/frappe-bench/env/lib/python3.10/site-packages/click/core.py", line 829, in __call__
    return self.main(*args, **kwargs)
  File "/home/admin123/frappe-bench/env/lib/python3.10/site-packages/click/core.py", line 782, in main
    rv = self.invoke(ctx)
  File "/home/admin123/frappe-bench/env/lib/python3.10/site-packages/click/core.py", line 1259, in invoke
    return _process_result(sub_ctx.command.invoke(sub_ctx))
  File "/home/admin123/frappe-bench/env/lib/python3.10/site-packages/click/core.py", line 1259, in invoke
    return _process_result(sub_ctx.command.invoke(sub_ctx))
  File "/home/admin123/frappe-bench/env/lib/python3.10/site-packages/click/core.py", line 1066, in invoke
    return ctx.invoke(self.callback, **ctx.params)
  File "/home/admin123/frappe-bench/env/lib/python3.10/site-packages/click/core.py", line 610, in invoke
    return callback(*args, **kwargs)
  File "/home/admin123/frappe-bench/apps/frappe/frappe/commands/scheduler.py", line 206, in start_worker
    start_worker(
  File "/home/admin123/frappe-bench/apps/frappe/frappe/utils/background_jobs.py", line 247, in start_worker
    redis_connection = get_redis_conn(username=rq_username, password=rq_password)
  File "/home/admin123/frappe-bench/env/lib/python3.10/site-packages/tenacity/__init__.py", line 324, in wrapped_f
    return self(f, *args, **kw)
  File "/home/admin123/frappe-bench/env/lib/python3.10/site-packages/tenacity/__init__.py", line 404, in __call__
    do = self.iter(retry_state=retry_state)
  File "/home/admin123/frappe-bench/env/lib/python3.10/site-packages/tenacity/__init__.py", line 361, in iter
    raise retry_exc from fut.exception()
tenacity.RetryError: RetryError[<Future at 0x7f8b47a4da50 state=finished raised ConnectionError>]
Traceback (most recent call last):
  File "/home/admin123/frappe-bench/env/lib/python3.10/site-packages/redis/connection.py", line 559, in connect
    sock = self._connect()
  File "/home/admin123/frappe-bench/env/lib/python3.10/site-packages/redis/connection.py", line 615, in _connect
    raise err
  File "/home/admin123/frappe-bench/env/lib/python3.10/site-packages/redis/connection.py", line 603, in _connect
    sock.connect(socket_address)
ConnectionRefusedError: [Errno 111] Connection refused

During handling of the above exception, another exception occurred:

Traceback (most recent call last):
  File "/home/admin123/frappe-bench/env/lib/python3.10/site-packages/tenacity/__init__.py", line 407, in __call__
    result = fn(*args, **kwargs)
  File "/home/admin123/frappe-bench/apps/frappe/frappe/utils/background_jobs.py", line 388, in get_redis_conn
    _redis_queue_conn = RedisQueue.get_connection()
  File "/home/admin123/frappe-bench/apps/frappe/frappe/utils/redis_queue.py", line 24, in get_connection
    conn.ping()
  File "/home/admin123/frappe-bench/env/lib/python3.10/site-packages/redis/client.py", line 1378, in ping
    return self.execute_command('PING')
  File "/home/admin123/frappe-bench/env/lib/python3.10/site-packages/redis/client.py", line 898, in execute_command
    conn = self.connection or pool.get_connection(command_name, **options)
  File "/home/admin123/frappe-bench/env/lib/python3.10/site-packages/redis/connection.py", line 1192, in get_connection
    connection.connect()
  File "/home/admin123/frappe-bench/env/lib/python3.10/site-packages/redis/connection.py", line 563, in connect
    raise ConnectionError(self._error_message(e))
redis.exceptions.ConnectionError: Error 111 connecting to localhost:11000. Connection refused.

The above exception was the direct cause of the following exception:

Traceback (most recent call last):
  File "/usr/lib/python3.10/runpy.py", line 196, in _run_module_as_main
    return _run_code(code, main_globals, None,
  File "/usr/lib/python3.10/runpy.py", line 86, in _run_code
    exec(code, run_globals)
  File "/home/admin123/frappe-bench/apps/frappe/frappe/utils/bench_helper.py", line 109, in <module>
    main()
  File "/home/admin123/frappe-bench/apps/frappe/frappe/utils/bench_helper.py", line 18, in main
    click.Group(commands=commands)(prog_name="bench")
  File "/home/admin123/frappe-bench/env/lib/python3.10/site-packages/click/core.py", line 829, in __call__
    return self.main(*args, **kwargs)
  File "/home/admin123/frappe-bench/env/lib/python3.10/site-packages/click/core.py", line 782, in main
    rv = self.invoke(ctx)
  File "/home/admin123/frappe-bench/env/lib/python3.10/site-packages/click/core.py", line 1259, in invoke
    return _process_result(sub_ctx.command.invoke(sub_ctx))
  File "/home/admin123/frappe-bench/env/lib/python3.10/site-packages/click/core.py", line 1259, in invoke
    return _process_result(sub_ctx.command.invoke(sub_ctx))
  File "/home/admin123/frappe-bench/env/lib/python3.10/site-packages/click/core.py", line 1066, in invoke
    return ctx.invoke(self.callback, **ctx.params)
  File "/home/admin123/frappe-bench/env/lib/python3.10/site-packages/click/core.py", line 610, in invoke
    return callback(*args, **kwargs)
  File "/home/admin123/frappe-bench/apps/frappe/frappe/commands/scheduler.py", line 206, in start_worker
    start_worker(
  File "/home/admin123/frappe-bench/apps/frappe/frappe/utils/background_jobs.py", line 247, in start_worker
    redis_connection = get_redis_conn(username=rq_username, password=rq_password)
  File "/home/admin123/frappe-bench/env/lib/python3.10/site-packages/tenacity/__init__.py", line 324, in wrapped_f
    return self(f, *args, **kw)
  File "/home/admin123/frappe-bench/env/lib/python3.10/site-packages/tenacity/__init__.py", line 404, in __call__
    do = self.iter(retry_state=retry_state)
  File "/home/admin123/frappe-bench/env/lib/python3.10/site-packages/tenacity/__init__.py", line 361, in iter
    raise retry_exc from fut.exception()
tenacity.RetryError: RetryError[<Future at 0x7fe82f30da50 state=finished raised ConnectionError>]
Traceback (most recent call last):
  File "/home/admin123/frappe-bench/env/lib/python3.10/site-packages/redis/connection.py", line 559, in connect
    sock = self._connect()
  File "/home/admin123/frappe-bench/env/lib/python3.10/site-packages/redis/connection.py", line 615, in _connect
    raise err
  File "/home/admin123/frappe-bench/env/lib/python3.10/site-packages/redis/connection.py", line 603, in _connect
    sock.connect(socket_address)
ConnectionRefusedError: [Errno 111] Connection refused

During handling of the above exception, another exception occurred:

Traceback (most recent call last):
  File "/home/admin123/frappe-bench/env/lib/python3.10/site-packages/tenacity/__init__.py", line 407, in __call__
    result = fn(*args, **kwargs)
  File "/home/admin123/frappe-bench/apps/frappe/frappe/utils/background_jobs.py", line 388, in get_redis_conn
    _redis_queue_conn = RedisQueue.get_connection()
  File "/home/admin123/frappe-bench/apps/frappe/frappe/utils/redis_queue.py", line 24, in get_connection
    conn.ping()
  File "/home/admin123/frappe-bench/env/lib/python3.10/site-packages/redis/client.py", line 1378, in ping
    return self.execute_command('PING')
  File "/home/admin123/frappe-bench/env/lib/python3.10/site-packages/redis/client.py", line 898, in execute_command
    conn = self.connection or pool.get_connection(command_name, **options)
  File "/home/admin123/frappe-bench/env/lib/python3.10/site-packages/redis/connection.py", line 1192, in get_connection
    connection.connect()
  File "/home/admin123/frappe-bench/env/lib/python3.10/site-packages/redis/connection.py", line 563, in connect
    raise ConnectionError(self._error_message(e))
redis.exceptions.ConnectionError: Error 111 connecting to localhost:11000. Connection refused.

The above exception was the direct cause of the following exception:

Traceback (most recent call last):
  File "/usr/lib/python3.10/runpy.py", line 196, in _run_module_as_main
    return _run_code(code, main_globals, None,
  File "/usr/lib/python3.10/runpy.py", line 86, in _run_code
    exec(code, run_globals)
  File "/home/admin123/frappe-bench/apps/frappe/frappe/utils/bench_helper.py", line 109, in <module>
    main()
  File "/home/admin123/frappe-bench/apps/frappe/frappe/utils/bench_helper.py", line 18, in main
    click.Group(commands=commands)(prog_name="bench")
  File "/home/admin123/frappe-bench/env/lib/python3.10/site-packages/click/core.py", line 829, in __call__
    return self.main(*args, **kwargs)
  File "/home/admin123/frappe-bench/env/lib/python3.10/site-packages/click/core.py", line 782, in main
    rv = self.invoke(ctx)
  File "/home/admin123/frappe-bench/env/lib/python3.10/site-packages/click/core.py", line 1259, in invoke
    return _process_result(sub_ctx.command.invoke(sub_ctx))
  File "/home/admin123/frappe-bench/env/lib/python3.10/site-packages/click/core.py", line 1259, in invoke
    return _process_result(sub_ctx.command.invoke(sub_ctx))
  File "/home/admin123/frappe-bench/env/lib/python3.10/site-packages/click/core.py", line 1066, in invoke
    return ctx.invoke(self.callback, **ctx.params)
  File "/home/admin123/frappe-bench/env/lib/python3.10/site-packages/click/core.py", line 610, in invoke
    return callback(*args, **kwargs)
  File "/home/admin123/frappe-bench/apps/frappe/frappe/commands/scheduler.py", line 206, in start_worker
    start_worker(
  File "/home/admin123/frappe-bench/apps/frappe/frappe/utils/background_jobs.py", line 247, in start_worker
    redis_connection = get_redis_conn(username=rq_username, password=rq_password)
  File "/home/admin123/frappe-bench/env/lib/python3.10/site-packages/tenacity/__init__.py", line 324, in wrapped_f
    return self(f, *args, **kw)
  File "/home/admin123/frappe-bench/env/lib/python3.10/site-packages/tenacity/__init__.py", line 404, in __call__
    do = self.iter(retry_state=retry_state)
  File "/home/admin123/frappe-bench/env/lib/python3.10/site-packages/tenacity/__init__.py", line 361, in iter
    raise retry_exc from fut.exception()
tenacity.RetryError: RetryError[<Future at 0x7fb87d629a50 state=finished raised ConnectionError>]
Traceback (most recent call last):
  File "/home/admin123/frappe-bench/env/lib/python3.10/site-packages/redis/connection.py", line 559, in connect
    sock = self._connect()
  File "/home/admin123/frappe-bench/env/lib/python3.10/site-packages/redis/connection.py", line 615, in _connect
    raise err
  File "/home/admin123/frappe-bench/env/lib/python3.10/site-packages/redis/connection.py", line 603, in _connect
    sock.connect(socket_address)
ConnectionRefusedError: [Errno 111] Connection refused

During handling of the above exception, another exception occurred:

Traceback (most recent call last):
  File "/home/admin123/frappe-bench/env/lib/python3.10/site-packages/tenacity/__init__.py", line 407, in __call__
    result = fn(*args, **kwargs)
  File "/home/admin123/frappe-bench/apps/frappe/frappe/utils/background_jobs.py", line 388, in get_redis_conn
    _redis_queue_conn = RedisQueue.get_connection()
  File "/home/admin123/frappe-bench/apps/frappe/frappe/utils/redis_queue.py", line 24, in get_connection
    conn.ping()
  File "/home/admin123/frappe-bench/env/lib/python3.10/site-packages/redis/client.py", line 1378, in ping
    return self.execute_command('PING')
  File "/home/admin123/frappe-bench/env/lib/python3.10/site-packages/redis/client.py", line 898, in execute_command
    conn = self.connection or pool.get_connection(command_name, **options)
  File "/home/admin123/frappe-bench/env/lib/python3.10/site-packages/redis/connection.py", line 1192, in get_connection
    connection.connect()
  File "/home/admin123/frappe-bench/env/lib/python3.10/site-packages/redis/connection.py", line 563, in connect
    raise ConnectionError(self._error_message(e))
redis.exceptions.ConnectionError: Error 111 connecting to localhost:11000. Connection refused.

The above exception was the direct cause of the following exception:

Traceback (most recent call last):
  File "/usr/lib/python3.10/runpy.py", line 196, in _run_module_as_main
    return _run_code(code, main_globals, None,
  File "/usr/lib/python3.10/runpy.py", line 86, in _run_code
    exec(code, run_globals)
  File "/home/admin123/frappe-bench/apps/frappe/frappe/utils/bench_helper.py", line 109, in <module>
    main()
  File "/home/admin123/frappe-bench/apps/frappe/frappe/utils/bench_helper.py", line 18, in main
    click.Group(commands=commands)(prog_name="bench")
  File "/home/admin123/frappe-bench/env/lib/python3.10/site-packages/click/core.py", line 829, in __call__
    return self.main(*args, **kwargs)
  File "/home/admin123/frappe-bench/env/lib/python3.10/site-packages/click/core.py", line 782, in main
    rv = self.invoke(ctx)
  File "/home/admin123/frappe-bench/env/lib/python3.10/site-packages/click/core.py", line 1259, in invoke
    return _process_result(sub_ctx.command.invoke(sub_ctx))
  File "/home/admin123/frappe-bench/env/lib/python3.10/site-packages/click/core.py", line 1259, in invoke
    return _process_result(sub_ctx.command.invoke(sub_ctx))
  File "/home/admin123/frappe-bench/env/lib/python3.10/site-packages/click/core.py", line 1066, in invoke
    return ctx.invoke(self.callback, **ctx.params)
  File "/home/admin123/frappe-bench/env/lib/python3.10/site-packages/click/core.py", line 610, in invoke
    return callback(*args, **kwargs)
  File "/home/admin123/frappe-bench/apps/frappe/frappe/commands/scheduler.py", line 206, in start_worker
    start_worker(
  File "/home/admin123/frappe-bench/apps/frappe/frappe/utils/background_jobs.py", line 247, in start_worker
    redis_connection = get_redis_conn(username=rq_username, password=rq_password)
  File "/home/admin123/frappe-bench/env/lib/python3.10/site-packages/tenacity/__init__.py", line 324, in wrapped_f
    return self(f, *args, **kw)
  File "/home/admin123/frappe-bench/env/lib/python3.10/site-packages/tenacity/__init__.py", line 404, in __call__
    do = self.iter(retry_state=retry_state)
  File "/home/admin123/frappe-bench/env/lib/python3.10/site-packages/tenacity/__init__.py", line 361, in iter
    raise retry_exc from fut.exception()
tenacity.RetryError: RetryError[<Future at 0x7f9aff4d5a50 state=finished raised ConnectionError>]
Traceback (most recent call last):
  File "/home/admin123/frappe-bench/env/lib/python3.10/site-packages/redis/connection.py", line 559, in connect
    sock = self._connect()
  File "/home/admin123/frappe-bench/env/lib/python3.10/site-packages/redis/connection.py", line 615, in _connect
    raise err
  File "/home/admin123/frappe-bench/env/lib/python3.10/site-packages/redis/connection.py", line 603, in _connect
    sock.connect(socket_address)
ConnectionRefusedError: [Errno 111] Connection refused

During handling of the above exception, another exception occurred:

Traceback (most recent call last):
  File "/home/admin123/frappe-bench/env/lib/python3.10/site-packages/tenacity/__init__.py", line 407, in __call__
    result = fn(*args, **kwargs)
  File "/home/admin123/frappe-bench/apps/frappe/frappe/utils/background_jobs.py", line 388, in get_redis_conn
    _redis_queue_conn = RedisQueue.get_connection()
  File "/home/admin123/frappe-bench/apps/frappe/frappe/utils/redis_queue.py", line 24, in get_connection
    conn.ping()
  File "/home/admin123/frappe-bench/env/lib/python3.10/site-packages/redis/client.py", line 1378, in ping
    return self.execute_command('PING')
  File "/home/admin123/frappe-bench/env/lib/python3.10/site-packages/redis/client.py", line 898, in execute_command
    conn = self.connection or pool.get_connection(command_name, **options)
  File "/home/admin123/frappe-bench/env/lib/python3.10/site-packages/redis/connection.py", line 1192, in get_connection
    connection.connect()
  File "/home/admin123/frappe-bench/env/lib/python3.10/site-packages/redis/connection.py", line 563, in connect
    raise ConnectionError(self._error_message(e))
redis.exceptions.ConnectionError: Error 111 connecting to localhost:11000. Connection refused.

The above exception was the direct cause of the following exception:

Traceback (most recent call last):
  File "/usr/lib/python3.10/runpy.py", line 196, in _run_module_as_main
    return _run_code(code, main_globals, None,
  File "/usr/lib/python3.10/runpy.py", line 86, in _run_code
    exec(code, run_globals)
  File "/home/admin123/frappe-bench/apps/frappe/frappe/utils/bench_helper.py", line 109, in <module>
    main()
  File "/home/admin123/frappe-bench/apps/frappe/frappe/utils/bench_helper.py", line 18, in main
    click.Group(commands=commands)(prog_name="bench")
  File "/home/admin123/frappe-bench/env/lib/python3.10/site-packages/click/core.py", line 829, in __call__
    return self.main(*args, **kwargs)
  File "/home/admin123/frappe-bench/env/lib/python3.10/site-packages/click/core.py", line 782, in main
    rv = self.invoke(ctx)
  File "/home/admin123/frappe-bench/env/lib/python3.10/site-packages/click/core.py", line 1259, in invoke
    return _process_result(sub_ctx.command.invoke(sub_ctx))
  File "/home/admin123/frappe-bench/env/lib/python3.10/site-packages/click/core.py", line 1259, in invoke
    return _process_result(sub_ctx.command.invoke(sub_ctx))
  File "/home/admin123/frappe-bench/env/lib/python3.10/site-packages/click/core.py", line 1066, in invoke
    return ctx.invoke(self.callback, **ctx.params)
  File "/home/admin123/frappe-bench/env/lib/python3.10/site-packages/click/core.py", line 610, in invoke
    return callback(*args, **kwargs)
  File "/home/admin123/frappe-bench/apps/frappe/frappe/commands/scheduler.py", line 206, in start_worker
    start_worker(
  File "/home/admin123/frappe-bench/apps/frappe/frappe/utils/background_jobs.py", line 247, in start_worker
    redis_connection = get_redis_conn(username=rq_username, password=rq_password)
  File "/home/admin123/frappe-bench/env/lib/python3.10/site-packages/tenacity/__init__.py", line 324, in wrapped_f
    return self(f, *args, **kw)
  File "/home/admin123/frappe-bench/env/lib/python3.10/site-packages/tenacity/__init__.py", line 404, in __call__
    do = self.iter(retry_state=retry_state)
  File "/home/admin123/frappe-bench/env/lib/python3.10/site-packages/tenacity/__init__.py", line 361, in iter
    raise retry_exc from fut.exception()
tenacity.RetryError: RetryError[<Future at 0x7f2cf63d5a50 state=finished raised ConnectionError>]
Traceback (most recent call last):
  File "/home/admin123/frappe-bench/env/lib/python3.10/site-packages/redis/connection.py", line 559, in connect
    sock = self._connect()
  File "/home/admin123/frappe-bench/env/lib/python3.10/site-packages/redis/connection.py", line 615, in _connect
    raise err
  File "/home/admin123/frappe-bench/env/lib/python3.10/site-packages/redis/connection.py", line 603, in _connect
    sock.connect(socket_address)
ConnectionRefusedError: [Errno 111] Connection refused

During handling of the above exception, another exception occurred:

Traceback (most recent call last):
  File "/home/admin123/frappe-bench/env/lib/python3.10/site-packages/tenacity/__init__.py", line 407, in __call__
    result = fn(*args, **kwargs)
  File "/home/admin123/frappe-bench/apps/frappe/frappe/utils/background_jobs.py", line 388, in get_redis_conn
    _redis_queue_conn = RedisQueue.get_connection()
  File "/home/admin123/frappe-bench/apps/frappe/frappe/utils/redis_queue.py", line 24, in get_connection
    conn.ping()
  File "/home/admin123/frappe-bench/env/lib/python3.10/site-packages/redis/client.py", line 1378, in ping
    return self.execute_command('PING')
  File "/home/admin123/frappe-bench/env/lib/python3.10/site-packages/redis/client.py", line 898, in execute_command
    conn = self.connection or pool.get_connection(command_name, **options)
  File "/home/admin123/frappe-bench/env/lib/python3.10/site-packages/redis/connection.py", line 1192, in get_connection
    connection.connect()
  File "/home/admin123/frappe-bench/env/lib/python3.10/site-packages/redis/connection.py", line 563, in connect
    raise ConnectionError(self._error_message(e))
redis.exceptions.ConnectionError: Error 111 connecting to localhost:11000. Connection refused.

The above exception was the direct cause of the following exception:

Traceback (most recent call last):
  File "/usr/lib/python3.10/runpy.py", line 196, in _run_module_as_main
    return _run_code(code, main_globals, None,
  File "/usr/lib/python3.10/runpy.py", line 86, in _run_code
    exec(code, run_globals)
  File "/home/admin123/frappe-bench/apps/frappe/frappe/utils/bench_helper.py", line 109, in <module>
    main()
  File "/home/admin123/frappe-bench/apps/frappe/frappe/utils/bench_helper.py", line 18, in main
    click.Group(commands=commands)(prog_name="bench")
  File "/home/admin123/frappe-bench/env/lib/python3.10/site-packages/click/core.py", line 829, in __call__
    return self.main(*args, **kwargs)
  File "/home/admin123/frappe-bench/env/lib/python3.10/site-packages/click/core.py", line 782, in main
    rv = self.invoke(ctx)
  File "/home/admin123/frappe-bench/env/lib/python3.10/site-packages/click/core.py", line 1259, in invoke
    return _process_result(sub_ctx.command.invoke(sub_ctx))
  File "/home/admin123/frappe-bench/env/lib/python3.10/site-packages/click/core.py", line 1259, in invoke
    return _process_result(sub_ctx.command.invoke(sub_ctx))
  File "/home/admin123/frappe-bench/env/lib/python3.10/site-packages/click/core.py", line 1066, in invoke
    return ctx.invoke(self.callback, **ctx.params)
  File "/home/admin123/frappe-bench/env/lib/python3.10/site-packages/click/core.py", line 610, in invoke
    return callback(*args, **kwargs)
  File "/home/admin123/frappe-bench/apps/frappe/frappe/commands/scheduler.py", line 206, in start_worker
    start_worker(
  File "/home/admin123/frappe-bench/apps/frappe/frappe/utils/background_jobs.py", line 247, in start_worker
    redis_connection = get_redis_conn(username=rq_username, password=rq_password)
  File "/home/admin123/frappe-bench/env/lib/python3.10/site-packages/tenacity/__init__.py", line 324, in wrapped_f
    return self(f, *args, **kw)
  File "/home/admin123/frappe-bench/env/lib/python3.10/site-packages/tenacity/__init__.py", line 404, in __call__
    do = self.iter(retry_state=retry_state)
  File "/home/admin123/frappe-bench/env/lib/python3.10/site-packages/tenacity/__init__.py", line 361, in iter
    raise retry_exc from fut.exception()
tenacity.RetryError: RetryError[<Future at 0x7f7d10ed5a50 state=finished raised ConnectionError>]
Traceback (most recent call last):
  File "/home/admin123/frappe-bench/env/lib/python3.10/site-packages/redis/connection.py", line 559, in connect
    sock = self._connect()
  File "/home/admin123/frappe-bench/env/lib/python3.10/site-packages/redis/connection.py", line 615, in _connect
    raise err
  File "/home/admin123/frappe-bench/env/lib/python3.10/site-packages/redis/connection.py", line 603, in _connect
    sock.connect(socket_address)
ConnectionRefusedError: [Errno 111] Connection refused

During handling of the above exception, another exception occurred:

Traceback (most recent call last):
  File "/home/admin123/frappe-bench/env/lib/python3.10/site-packages/tenacity/__init__.py", line 407, in __call__
    result = fn(*args, **kwargs)
  File "/home/admin123/frappe-bench/apps/frappe/frappe/utils/background_jobs.py", line 388, in get_redis_conn
    _redis_queue_conn = RedisQueue.get_connection()
  File "/home/admin123/frappe-bench/apps/frappe/frappe/utils/redis_queue.py", line 24, in get_connection
    conn.ping()
  File "/home/admin123/frappe-bench/env/lib/python3.10/site-packages/redis/client.py", line 1378, in ping
    return self.execute_command('PING')
  File "/home/admin123/frappe-bench/env/lib/python3.10/site-packages/redis/client.py", line 898, in execute_command
    conn = self.connection or pool.get_connection(command_name, **options)
  File "/home/admin123/frappe-bench/env/lib/python3.10/site-packages/redis/connection.py", line 1192, in get_connection
    connection.connect()
  File "/home/admin123/frappe-bench/env/lib/python3.10/site-packages/redis/connection.py", line 563, in connect
    raise ConnectionError(self._error_message(e))
redis.exceptions.ConnectionError: Error 111 connecting to localhost:11000. Connection refused.

The above exception was the direct cause of the following exception:

Traceback (most recent call last):
  File "/usr/lib/python3.10/runpy.py", line 196, in _run_module_as_main
    return _run_code(code, main_globals, None,
  File "/usr/lib/python3.10/runpy.py", line 86, in _run_code
    exec(code, run_globals)
  File "/home/admin123/frappe-bench/apps/frappe/frappe/utils/bench_helper.py", line 109, in <module>
    main()
  File "/home/admin123/frappe-bench/apps/frappe/frappe/utils/bench_helper.py", line 18, in main
    click.Group(commands=commands)(prog_name="bench")
  File "/home/admin123/frappe-bench/env/lib/python3.10/site-packages/click/core.py", line 829, in __call__
    return self.main(*args, **kwargs)
  File "/home/admin123/frappe-bench/env/lib/python3.10/site-packages/click/core.py", line 782, in main
    rv = self.invoke(ctx)
  File "/home/admin123/frappe-bench/env/lib/python3.10/site-packages/click/core.py", line 1259, in invoke
    return _process_result(sub_ctx.command.invoke(sub_ctx))
  File "/home/admin123/frappe-bench/env/lib/python3.10/site-packages/click/core.py", line 1259, in invoke
    return _process_result(sub_ctx.command.invoke(sub_ctx))
  File "/home/admin123/frappe-bench/env/lib/python3.10/site-packages/click/core.py", line 1066, in invoke
    return ctx.invoke(self.callback, **ctx.params)
  File "/home/admin123/frappe-bench/env/lib/python3.10/site-packages/click/core.py", line 610, in invoke
    return callback(*args, **kwargs)
  File "/home/admin123/frappe-bench/apps/frappe/frappe/commands/scheduler.py", line 206, in start_worker
    start_worker(
  File "/home/admin123/frappe-bench/apps/frappe/frappe/utils/background_jobs.py", line 247, in start_worker
    redis_connection = get_redis_conn(username=rq_username, password=rq_password)
  File "/home/admin123/frappe-bench/env/lib/python3.10/site-packages/tenacity/__init__.py", line 324, in wrapped_f
    return self(f, *args, **kw)
  File "/home/admin123/frappe-bench/env/lib/python3.10/site-packages/tenacity/__init__.py", line 404, in __call__
    do = self.iter(retry_state=retry_state)
  File "/home/admin123/frappe-bench/env/lib/python3.10/site-packages/tenacity/__init__.py", line 361, in iter
    raise retry_exc from fut.exception()
tenacity.RetryError: RetryError[<Future at 0x7f6fb4271a50 state=finished raised ConnectionError>]
Traceback (most recent call last):
  File "/home/admin123/frappe-bench/env/lib/python3.10/site-packages/redis/connection.py", line 559, in connect
    sock = self._connect()
  File "/home/admin123/frappe-bench/env/lib/python3.10/site-packages/redis/connection.py", line 615, in _connect
    raise err
  File "/home/admin123/frappe-bench/env/lib/python3.10/site-packages/redis/connection.py", line 603, in _connect
    sock.connect(socket_address)
ConnectionRefusedError: [Errno 111] Connection refused

During handling of the above exception, another exception occurred:

Traceback (most recent call last):
  File "/home/admin123/frappe-bench/env/lib/python3.10/site-packages/tenacity/__init__.py", line 407, in __call__
    result = fn(*args, **kwargs)
  File "/home/admin123/frappe-bench/apps/frappe/frappe/utils/background_jobs.py", line 388, in get_redis_conn
    _redis_queue_conn = RedisQueue.get_connection()
  File "/home/admin123/frappe-bench/apps/frappe/frappe/utils/redis_queue.py", line 24, in get_connection
    conn.ping()
  File "/home/admin123/frappe-bench/env/lib/python3.10/site-packages/redis/client.py", line 1378, in ping
    return self.execute_command('PING')
  File "/home/admin123/frappe-bench/env/lib/python3.10/site-packages/redis/client.py", line 898, in execute_command
    conn = self.connection or pool.get_connection(command_name, **options)
  File "/home/admin123/frappe-bench/env/lib/python3.10/site-packages/redis/connection.py", line 1192, in get_connection
    connection.connect()
  File "/home/admin123/frappe-bench/env/lib/python3.10/site-packages/redis/connection.py", line 563, in connect
    raise ConnectionError(self._error_message(e))
redis.exceptions.ConnectionError: Error 111 connecting to localhost:11000. Connection refused.

The above exception was the direct cause of the following exception:

Traceback (most recent call last):
  File "/usr/lib/python3.10/runpy.py", line 196, in _run_module_as_main
    return _run_code(code, main_globals, None,
  File "/usr/lib/python3.10/runpy.py", line 86, in _run_code
    exec(code, run_globals)
  File "/home/admin123/frappe-bench/apps/frappe/frappe/utils/bench_helper.py", line 109, in <module>
    main()
  File "/home/admin123/frappe-bench/apps/frappe/frappe/utils/bench_helper.py", line 18, in main
    click.Group(commands=commands)(prog_name="bench")
  File "/home/admin123/frappe-bench/env/lib/python3.10/site-packages/click/core.py", line 829, in __call__
    return self.main(*args, **kwargs)
  File "/home/admin123/frappe-bench/env/lib/python3.10/site-packages/click/core.py", line 782, in main
    rv = self.invoke(ctx)
  File "/home/admin123/frappe-bench/env/lib/python3.10/site-packages/click/core.py", line 1259, in invoke
    return _process_result(sub_ctx.command.invoke(sub_ctx))
  File "/home/admin123/frappe-bench/env/lib/python3.10/site-packages/click/core.py", line 1259, in invoke
    return _process_result(sub_ctx.command.invoke(sub_ctx))
  File "/home/admin123/frappe-bench/env/lib/python3.10/site-packages/click/core.py", line 1066, in invoke
    return ctx.invoke(self.callback, **ctx.params)
  File "/home/admin123/frappe-bench/env/lib/python3.10/site-packages/click/core.py", line 610, in invoke
    return callback(*args, **kwargs)
  File "/home/admin123/frappe-bench/apps/frappe/frappe/commands/scheduler.py", line 206, in start_worker
    start_worker(
  File "/home/admin123/frappe-bench/apps/frappe/frappe/utils/background_jobs.py", line 247, in start_worker
    redis_connection = get_redis_conn(username=rq_username, password=rq_password)
  File "/home/admin123/frappe-bench/env/lib/python3.10/site-packages/tenacity/__init__.py", line 324, in wrapped_f
    return self(f, *args, **kw)
  File "/home/admin123/frappe-bench/env/lib/python3.10/site-packages/tenacity/__init__.py", line 404, in __call__
    do = self.iter(retry_state=retry_state)
  File "/home/admin123/frappe-bench/env/lib/python3.10/site-packages/tenacity/__init__.py", line 361, in iter
    raise retry_exc from fut.exception()
tenacity.RetryError: RetryError[<Future at 0x7fe9b0e05a50 state=finished raised ConnectionError>]
Traceback (most recent call last):
  File "/home/admin123/frappe-bench/env/lib/python3.10/site-packages/redis/connection.py", line 559, in connect
    sock = self._connect()
  File "/home/admin123/frappe-bench/env/lib/python3.10/site-packages/redis/connection.py", line 615, in _connect
    raise err
  File "/home/admin123/frappe-bench/env/lib/python3.10/site-packages/redis/connection.py", line 603, in _connect
    sock.connect(socket_address)
ConnectionRefusedError: [Errno 111] Connection refused

During handling of the above exception, another exception occurred:

Traceback (most recent call last):
  File "/home/admin123/frappe-bench/env/lib/python3.10/site-packages/tenacity/__init__.py", line 407, in __call__
    result = fn(*args, **kwargs)
  File "/home/admin123/frappe-bench/apps/frappe/frappe/utils/background_jobs.py", line 388, in get_redis_conn
    _redis_queue_conn = RedisQueue.get_connection()
  File "/home/admin123/frappe-bench/apps/frappe/frappe/utils/redis_queue.py", line 24, in get_connection
    conn.ping()
  File "/home/admin123/frappe-bench/env/lib/python3.10/site-packages/redis/client.py", line 1378, in ping
    return self.execute_command('PING')
  File "/home/admin123/frappe-bench/env/lib/python3.10/site-packages/redis/client.py", line 898, in execute_command
    conn = self.connection or pool.get_connection(command_name, **options)
  File "/home/admin123/frappe-bench/env/lib/python3.10/site-packages/redis/connection.py", line 1192, in get_connection
    connection.connect()
  File "/home/admin123/frappe-bench/env/lib/python3.10/site-packages/redis/connection.py", line 563, in connect
    raise ConnectionError(self._error_message(e))
redis.exceptions.ConnectionError: Error 111 connecting to localhost:11000. Connection refused.

The above exception was the direct cause of the following exception:

Traceback (most recent call last):
  File "/usr/lib/python3.10/runpy.py", line 196, in _run_module_as_main
    return _run_code(code, main_globals, None,
  File "/usr/lib/python3.10/runpy.py", line 86, in _run_code
    exec(code, run_globals)
  File "/home/admin123/frappe-bench/apps/frappe/frappe/utils/bench_helper.py", line 109, in <module>
    main()
  File "/home/admin123/frappe-bench/apps/frappe/frappe/utils/bench_helper.py", line 18, in main
    click.Group(commands=commands)(prog_name="bench")
  File "/home/admin123/frappe-bench/env/lib/python3.10/site-packages/click/core.py", line 829, in __call__
    return self.main(*args, **kwargs)
  File "/home/admin123/frappe-bench/env/lib/python3.10/site-packages/click/core.py", line 782, in main
    rv = self.invoke(ctx)
  File "/home/admin123/frappe-bench/env/lib/python3.10/site-packages/click/core.py", line 1259, in invoke
    return _process_result(sub_ctx.command.invoke(sub_ctx))
  File "/home/admin123/frappe-bench/env/lib/python3.10/site-packages/click/core.py", line 1259, in invoke
    return _process_result(sub_ctx.command.invoke(sub_ctx))
  File "/home/admin123/frappe-bench/env/lib/python3.10/site-packages/click/core.py", line 1066, in invoke
    return ctx.invoke(self.callback, **ctx.params)
  File "/home/admin123/frappe-bench/env/lib/python3.10/site-packages/click/core.py", line 610, in invoke
    return callback(*args, **kwargs)
  File "/home/admin123/frappe-bench/apps/frappe/frappe/commands/scheduler.py", line 206, in start_worker
    start_worker(
  File "/home/admin123/frappe-bench/apps/frappe/frappe/utils/background_jobs.py", line 247, in start_worker
    redis_connection = get_redis_conn(username=rq_username, password=rq_password)
  File "/home/admin123/frappe-bench/env/lib/python3.10/site-packages/tenacity/__init__.py", line 324, in wrapped_f
    return self(f, *args, **kw)
  File "/home/admin123/frappe-bench/env/lib/python3.10/site-packages/tenacity/__init__.py", line 404, in __call__
    do = self.iter(retry_state=retry_state)
  File "/home/admin123/frappe-bench/env/lib/python3.10/site-packages/tenacity/__init__.py", line 361, in iter
    raise retry_exc from fut.exception()
tenacity.RetryError: RetryError[<Future at 0x7f3969fc9a50 state=finished raised ConnectionError>]
Traceback (most recent call last):
  File "/home/admin123/frappe-bench/env/lib/python3.10/site-packages/redis/connection.py", line 559, in connect
    sock = self._connect()
  File "/home/admin123/frappe-bench/env/lib/python3.10/site-packages/redis/connection.py", line 615, in _connect
    raise err
  File "/home/admin123/frappe-bench/env/lib/python3.10/site-packages/redis/connection.py", line 603, in _connect
    sock.connect(socket_address)
ConnectionRefusedError: [Errno 111] Connection refused

During handling of the above exception, another exception occurred:

Traceback (most recent call last):
  File "/home/admin123/frappe-bench/env/lib/python3.10/site-packages/tenacity/__init__.py", line 407, in __call__
    result = fn(*args, **kwargs)
  File "/home/admin123/frappe-bench/apps/frappe/frappe/utils/background_jobs.py", line 388, in get_redis_conn
    _redis_queue_conn = RedisQueue.get_connection()
  File "/home/admin123/frappe-bench/apps/frappe/frappe/utils/redis_queue.py", line 24, in get_connection
    conn.ping()
  File "/home/admin123/frappe-bench/env/lib/python3.10/site-packages/redis/client.py", line 1378, in ping
    return self.execute_command('PING')
  File "/home/admin123/frappe-bench/env/lib/python3.10/site-packages/redis/client.py", line 898, in execute_command
    conn = self.connection or pool.get_connection(command_name, **options)
  File "/home/admin123/frappe-bench/env/lib/python3.10/site-packages/redis/connection.py", line 1192, in get_connection
    connection.connect()
  File "/home/admin123/frappe-bench/env/lib/python3.10/site-packages/redis/connection.py", line 563, in connect
    raise ConnectionError(self._error_message(e))
redis.exceptions.ConnectionError: Error 111 connecting to localhost:11000. Connection refused.

The above exception was the direct cause of the following exception:

Traceback (most recent call last):
  File "/usr/lib/python3.10/runpy.py", line 196, in _run_module_as_main
    return _run_code(code, main_globals, None,
  File "/usr/lib/python3.10/runpy.py", line 86, in _run_code
    exec(code, run_globals)
  File "/home/admin123/frappe-bench/apps/frappe/frappe/utils/bench_helper.py", line 109, in <module>
    main()
  File "/home/admin123/frappe-bench/apps/frappe/frappe/utils/bench_helper.py", line 18, in main
    click.Group(commands=commands)(prog_name="bench")
  File "/home/admin123/frappe-bench/env/lib/python3.10/site-packages/click/core.py", line 829, in __call__
    return self.main(*args, **kwargs)
  File "/home/admin123/frappe-bench/env/lib/python3.10/site-packages/click/core.py", line 782, in main
    rv = self.invoke(ctx)
  File "/home/admin123/frappe-bench/env/lib/python3.10/site-packages/click/core.py", line 1259, in invoke
    return _process_result(sub_ctx.command.invoke(sub_ctx))
  File "/home/admin123/frappe-bench/env/lib/python3.10/site-packages/click/core.py", line 1259, in invoke
    return _process_result(sub_ctx.command.invoke(sub_ctx))
  File "/home/admin123/frappe-bench/env/lib/python3.10/site-packages/click/core.py", line 1066, in invoke
    return ctx.invoke(self.callback, **ctx.params)
  File "/home/admin123/frappe-bench/env/lib/python3.10/site-packages/click/core.py", line 610, in invoke
    return callback(*args, **kwargs)
  File "/home/admin123/frappe-bench/apps/frappe/frappe/commands/scheduler.py", line 206, in start_worker
    start_worker(
  File "/home/admin123/frappe-bench/apps/frappe/frappe/utils/background_jobs.py", line 247, in start_worker
    redis_connection = get_redis_conn(username=rq_username, password=rq_password)
  File "/home/admin123/frappe-bench/env/lib/python3.10/site-packages/tenacity/__init__.py", line 324, in wrapped_f
    return self(f, *args, **kw)
  File "/home/admin123/frappe-bench/env/lib/python3.10/site-packages/tenacity/__init__.py", line 404, in __call__
    do = self.iter(retry_state=retry_state)
  File "/home/admin123/frappe-bench/env/lib/python3.10/site-packages/tenacity/__init__.py", line 361, in iter
    raise retry_exc from fut.exception()
tenacity.RetryError: RetryError[<Future at 0x7f11b3129a50 state=finished raised ConnectionError>]
Traceback (most recent call last):
  File "/home/admin123/frappe-bench/env/lib/python3.10/site-packages/redis/connection.py", line 559, in connect
    sock = self._connect()
  File "/home/admin123/frappe-bench/env/lib/python3.10/site-packages/redis/connection.py", line 615, in _connect
    raise err
  File "/home/admin123/frappe-bench/env/lib/python3.10/site-packages/redis/connection.py", line 603, in _connect
    sock.connect(socket_address)
ConnectionRefusedError: [Errno 111] Connection refused

During handling of the above exception, another exception occurred:

Traceback (most recent call last):
  File "/home/admin123/frappe-bench/env/lib/python3.10/site-packages/tenacity/__init__.py", line 407, in __call__
    result = fn(*args, **kwargs)
  File "/home/admin123/frappe-bench/apps/frappe/frappe/utils/background_jobs.py", line 388, in get_redis_conn
    _redis_queue_conn = RedisQueue.get_connection()
  File "/home/admin123/frappe-bench/apps/frappe/frappe/utils/redis_queue.py", line 24, in get_connection
    conn.ping()
  File "/home/admin123/frappe-bench/env/lib/python3.10/site-packages/redis/client.py", line 1378, in ping
    return self.execute_command('PING')
  File "/home/admin123/frappe-bench/env/lib/python3.10/site-packages/redis/client.py", line 898, in execute_command
    conn = self.connection or pool.get_connection(command_name, **options)
  File "/home/admin123/frappe-bench/env/lib/python3.10/site-packages/redis/connection.py", line 1192, in get_connection
    connection.connect()
  File "/home/admin123/frappe-bench/env/lib/python3.10/site-packages/redis/connection.py", line 563, in connect
    raise ConnectionError(self._error_message(e))
redis.exceptions.ConnectionError: Error 111 connecting to localhost:11000. Connection refused.

The above exception was the direct cause of the following exception:

Traceback (most recent call last):
  File "/usr/lib/python3.10/runpy.py", line 196, in _run_module_as_main
    return _run_code(code, main_globals, None,
  File "/usr/lib/python3.10/runpy.py", line 86, in _run_code
    exec(code, run_globals)
  File "/home/admin123/frappe-bench/apps/frappe/frappe/utils/bench_helper.py", line 109, in <module>
    main()
  File "/home/admin123/frappe-bench/apps/frappe/frappe/utils/bench_helper.py", line 18, in main
    click.Group(commands=commands)(prog_name="bench")
  File "/home/admin123/frappe-bench/env/lib/python3.10/site-packages/click/core.py", line 829, in __call__
    return self.main(*args, **kwargs)
  File "/home/admin123/frappe-bench/env/lib/python3.10/site-packages/click/core.py", line 782, in main
    rv = self.invoke(ctx)
  File "/home/admin123/frappe-bench/env/lib/python3.10/site-packages/click/core.py", line 1259, in invoke
    return _process_result(sub_ctx.command.invoke(sub_ctx))
  File "/home/admin123/frappe-bench/env/lib/python3.10/site-packages/click/core.py", line 1259, in invoke
    return _process_result(sub_ctx.command.invoke(sub_ctx))
  File "/home/admin123/frappe-bench/env/lib/python3.10/site-packages/click/core.py", line 1066, in invoke
    return ctx.invoke(self.callback, **ctx.params)
  File "/home/admin123/frappe-bench/env/lib/python3.10/site-packages/click/core.py", line 610, in invoke
    return callback(*args, **kwargs)
  File "/home/admin123/frappe-bench/apps/frappe/frappe/commands/scheduler.py", line 206, in start_worker
    start_worker(
  File "/home/admin123/frappe-bench/apps/frappe/frappe/utils/background_jobs.py", line 247, in start_worker
    redis_connection = get_redis_conn(username=rq_username, password=rq_password)
  File "/home/admin123/frappe-bench/env/lib/python3.10/site-packages/tenacity/__init__.py", line 324, in wrapped_f
    return self(f, *args, **kw)
  File "/home/admin123/frappe-bench/env/lib/python3.10/site-packages/tenacity/__init__.py", line 404, in __call__
    do = self.iter(retry_state=retry_state)
  File "/home/admin123/frappe-bench/env/lib/python3.10/site-packages/tenacity/__init__.py", line 361, in iter
    raise retry_exc from fut.exception()
tenacity.RetryError: RetryError[<Future at 0x7f7676ea5a50 state=finished raised ConnectionError>]
Traceback (most recent call last):
  File "/home/admin123/frappe-bench/env/lib/python3.10/site-packages/redis/connection.py", line 559, in connect
    sock = self._connect()
  File "/home/admin123/frappe-bench/env/lib/python3.10/site-packages/redis/connection.py", line 615, in _connect
    raise err
  File "/home/admin123/frappe-bench/env/lib/python3.10/site-packages/redis/connection.py", line 603, in _connect
    sock.connect(socket_address)
ConnectionRefusedError: [Errno 111] Connection refused

During handling of the above exception, another exception occurred:

Traceback (most recent call last):
  File "/home/admin123/frappe-bench/env/lib/python3.10/site-packages/tenacity/__init__.py", line 407, in __call__
    result = fn(*args, **kwargs)
  File "/home/admin123/frappe-bench/apps/frappe/frappe/utils/background_jobs.py", line 388, in get_redis_conn
    _redis_queue_conn = RedisQueue.get_connection()
  File "/home/admin123/frappe-bench/apps/frappe/frappe/utils/redis_queue.py", line 24, in get_connection
    conn.ping()
  File "/home/admin123/frappe-bench/env/lib/python3.10/site-packages/redis/client.py", line 1378, in ping
    return self.execute_command('PING')
  File "/home/admin123/frappe-bench/env/lib/python3.10/site-packages/redis/client.py", line 898, in execute_command
    conn = self.connection or pool.get_connection(command_name, **options)
  File "/home/admin123/frappe-bench/env/lib/python3.10/site-packages/redis/connection.py", line 1192, in get_connection
    connection.connect()
  File "/home/admin123/frappe-bench/env/lib/python3.10/site-packages/redis/connection.py", line 563, in connect
    raise ConnectionError(self._error_message(e))
redis.exceptions.ConnectionError: Error 111 connecting to localhost:11000. Connection refused.

The above exception was the direct cause of the following exception:

Traceback (most recent call last):
  File "/usr/lib/python3.10/runpy.py", line 196, in _run_module_as_main
    return _run_code(code, main_globals, None,
  File "/usr/lib/python3.10/runpy.py", line 86, in _run_code
    exec(code, run_globals)
  File "/home/admin123/frappe-bench/apps/frappe/frappe/utils/bench_helper.py", line 109, in <module>
    main()
  File "/home/admin123/frappe-bench/apps/frappe/frappe/utils/bench_helper.py", line 18, in main
    click.Group(commands=commands)(prog_name="bench")
  File "/home/admin123/frappe-bench/env/lib/python3.10/site-packages/click/core.py", line 829, in __call__
    return self.main(*args, **kwargs)
  File "/home/admin123/frappe-bench/env/lib/python3.10/site-packages/click/core.py", line 782, in main
    rv = self.invoke(ctx)
  File "/home/admin123/frappe-bench/env/lib/python3.10/site-packages/click/core.py", line 1259, in invoke
    return _process_result(sub_ctx.command.invoke(sub_ctx))
  File "/home/admin123/frappe-bench/env/lib/python3.10/site-packages/click/core.py", line 1259, in invoke
    return _process_result(sub_ctx.command.invoke(sub_ctx))
  File "/home/admin123/frappe-bench/env/lib/python3.10/site-packages/click/core.py", line 1066, in invoke
    return ctx.invoke(self.callback, **ctx.params)
  File "/home/admin123/frappe-bench/env/lib/python3.10/site-packages/click/core.py", line 610, in invoke
    return callback(*args, **kwargs)
  File "/home/admin123/frappe-bench/apps/frappe/frappe/commands/scheduler.py", line 206, in start_worker
    start_worker(
  File "/home/admin123/frappe-bench/apps/frappe/frappe/utils/background_jobs.py", line 247, in start_worker
    redis_connection = get_redis_conn(username=rq_username, password=rq_password)
  File "/home/admin123/frappe-bench/env/lib/python3.10/site-packages/tenacity/__init__.py", line 324, in wrapped_f
    return self(f, *args, **kw)
  File "/home/admin123/frappe-bench/env/lib/python3.10/site-packages/tenacity/__init__.py", line 404, in __call__
    do = self.iter(retry_state=retry_state)
  File "/home/admin123/frappe-bench/env/lib/python3.10/site-packages/tenacity/__init__.py", line 361, in iter
    raise retry_exc from fut.exception()
tenacity.RetryError: RetryError[<Future at 0x7f0a379c9a50 state=finished raised ConnectionError>]
Traceback (most recent call last):
  File "/home/admin123/frappe-bench/env/lib/python3.10/site-packages/redis/connection.py", line 559, in connect
    sock = self._connect()
  File "/home/admin123/frappe-bench/env/lib/python3.10/site-packages/redis/connection.py", line 615, in _connect
    raise err
  File "/home/admin123/frappe-bench/env/lib/python3.10/site-packages/redis/connection.py", line 603, in _connect
    sock.connect(socket_address)
ConnectionRefusedError: [Errno 111] Connection refused

During handling of the above exception, another exception occurred:

Traceback (most recent call last):
  File "/home/admin123/frappe-bench/env/lib/python3.10/site-packages/tenacity/__init__.py", line 407, in __call__
    result = fn(*args, **kwargs)
  File "/home/admin123/frappe-bench/apps/frappe/frappe/utils/background_jobs.py", line 388, in get_redis_conn
    _redis_queue_conn = RedisQueue.get_connection()
  File "/home/admin123/frappe-bench/apps/frappe/frappe/utils/redis_queue.py", line 24, in get_connection
    conn.ping()
  File "/home/admin123/frappe-bench/env/lib/python3.10/site-packages/redis/client.py", line 1378, in ping
    return self.execute_command('PING')
  File "/home/admin123/frappe-bench/env/lib/python3.10/site-packages/redis/client.py", line 898, in execute_command
    conn = self.connection or pool.get_connection(command_name, **options)
  File "/home/admin123/frappe-bench/env/lib/python3.10/site-packages/redis/connection.py", line 1192, in get_connection
    connection.connect()
  File "/home/admin123/frappe-bench/env/lib/python3.10/site-packages/redis/connection.py", line 563, in connect
    raise ConnectionError(self._error_message(e))
redis.exceptions.ConnectionError: Error 111 connecting to localhost:11000. Connection refused.

The above exception was the direct cause of the following exception:

Traceback (most recent call last):
  File "/usr/lib/python3.10/runpy.py", line 196, in _run_module_as_main
    return _run_code(code, main_globals, None,
  File "/usr/lib/python3.10/runpy.py", line 86, in _run_code
    exec(code, run_globals)
  File "/home/admin123/frappe-bench/apps/frappe/frappe/utils/bench_helper.py", line 109, in <module>
    main()
  File "/home/admin123/frappe-bench/apps/frappe/frappe/utils/bench_helper.py", line 18, in main
    click.Group(commands=commands)(prog_name="bench")
  File "/home/admin123/frappe-bench/env/lib/python3.10/site-packages/click/core.py", line 829, in __call__
    return self.main(*args, **kwargs)
  File "/home/admin123/frappe-bench/env/lib/python3.10/site-packages/click/core.py", line 782, in main
    rv = self.invoke(ctx)
  File "/home/admin123/frappe-bench/env/lib/python3.10/site-packages/click/core.py", line 1259, in invoke
    return _process_result(sub_ctx.command.invoke(sub_ctx))
  File "/home/admin123/frappe-bench/env/lib/python3.10/site-packages/click/core.py", line 1259, in invoke
    return _process_result(sub_ctx.command.invoke(sub_ctx))
  File "/home/admin123/frappe-bench/env/lib/python3.10/site-packages/click/core.py", line 1066, in invoke
    return ctx.invoke(self.callback, **ctx.params)
  File "/home/admin123/frappe-bench/env/lib/python3.10/site-packages/click/core.py", line 610, in invoke
    return callback(*args, **kwargs)
  File "/home/admin123/frappe-bench/apps/frappe/frappe/commands/scheduler.py", line 206, in start_worker
    start_worker(
  File "/home/admin123/frappe-bench/apps/frappe/frappe/utils/background_jobs.py", line 247, in start_worker
    redis_connection = get_redis_conn(username=rq_username, password=rq_password)
  File "/home/admin123/frappe-bench/env/lib/python3.10/site-packages/tenacity/__init__.py", line 324, in wrapped_f
    return self(f, *args, **kw)
  File "/home/admin123/frappe-bench/env/lib/python3.10/site-packages/tenacity/__init__.py", line 404, in __call__
    do = self.iter(retry_state=retry_state)
  File "/home/admin123/frappe-bench/env/lib/python3.10/site-packages/tenacity/__init__.py", line 361, in iter
    raise retry_exc from fut.exception()
tenacity.RetryError: RetryError[<Future at 0x7f8e0eea1a50 state=finished raised ConnectionError>]
Traceback (most recent call last):
  File "/home/admin123/frappe-bench/env/lib/python3.10/site-packages/redis/connection.py", line 559, in connect
    sock = self._connect()
  File "/home/admin123/frappe-bench/env/lib/python3.10/site-packages/redis/connection.py", line 615, in _connect
    raise err
  File "/home/admin123/frappe-bench/env/lib/python3.10/site-packages/redis/connection.py", line 603, in _connect
    sock.connect(socket_address)
ConnectionRefusedError: [Errno 111] Connection refused

During handling of the above exception, another exception occurred:

Traceback (most recent call last):
  File "/home/admin123/frappe-bench/env/lib/python3.10/site-packages/tenacity/__init__.py", line 407, in __call__
    result = fn(*args, **kwargs)
  File "/home/admin123/frappe-bench/apps/frappe/frappe/utils/background_jobs.py", line 388, in get_redis_conn
    _redis_queue_conn = RedisQueue.get_connection()
  File "/home/admin123/frappe-bench/apps/frappe/frappe/utils/redis_queue.py", line 24, in get_connection
    conn.ping()
  File "/home/admin123/frappe-bench/env/lib/python3.10/site-packages/redis/client.py", line 1378, in ping
    return self.execute_command('PING')
  File "/home/admin123/frappe-bench/env/lib/python3.10/site-packages/redis/client.py", line 898, in execute_command
    conn = self.connection or pool.get_connection(command_name, **options)
  File "/home/admin123/frappe-bench/env/lib/python3.10/site-packages/redis/connection.py", line 1192, in get_connection
    connection.connect()
  File "/home/admin123/frappe-bench/env/lib/python3.10/site-packages/redis/connection.py", line 563, in connect
    raise ConnectionError(self._error_message(e))
redis.exceptions.ConnectionError: Error 111 connecting to localhost:11000. Connection refused.

The above exception was the direct cause of the following exception:

Traceback (most recent call last):
  File "/usr/lib/python3.10/runpy.py", line 196, in _run_module_as_main
    return _run_code(code, main_globals, None,
  File "/usr/lib/python3.10/runpy.py", line 86, in _run_code
    exec(code, run_globals)
  File "/home/admin123/frappe-bench/apps/frappe/frappe/utils/bench_helper.py", line 109, in <module>
    main()
  File "/home/admin123/frappe-bench/apps/frappe/frappe/utils/bench_helper.py", line 18, in main
    click.Group(commands=commands)(prog_name="bench")
  File "/home/admin123/frappe-bench/env/lib/python3.10/site-packages/click/core.py", line 829, in __call__
    return self.main(*args, **kwargs)
  File "/home/admin123/frappe-bench/env/lib/python3.10/site-packages/click/core.py", line 782, in main
    rv = self.invoke(ctx)
  File "/home/admin123/frappe-bench/env/lib/python3.10/site-packages/click/core.py", line 1259, in invoke
    return _process_result(sub_ctx.command.invoke(sub_ctx))
  File "/home/admin123/frappe-bench/env/lib/python3.10/site-packages/click/core.py", line 1259, in invoke
    return _process_result(sub_ctx.command.invoke(sub_ctx))
  File "/home/admin123/frappe-bench/env/lib/python3.10/site-packages/click/core.py", line 1066, in invoke
    return ctx.invoke(self.callback, **ctx.params)
  File "/home/admin123/frappe-bench/env/lib/python3.10/site-packages/click/core.py", line 610, in invoke
    return callback(*args, **kwargs)
  File "/home/admin123/frappe-bench/apps/frappe/frappe/commands/scheduler.py", line 206, in start_worker
    start_worker(
  File "/home/admin123/frappe-bench/apps/frappe/frappe/utils/background_jobs.py", line 247, in start_worker
    redis_connection = get_redis_conn(username=rq_username, password=rq_password)
  File "/home/admin123/frappe-bench/env/lib/python3.10/site-packages/tenacity/__init__.py", line 324, in wrapped_f
    return self(f, *args, **kw)
  File "/home/admin123/frappe-bench/env/lib/python3.10/site-packages/tenacity/__init__.py", line 404, in __call__
    do = self.iter(retry_state=retry_state)
  File "/home/admin123/frappe-bench/env/lib/python3.10/site-packages/tenacity/__init__.py", line 361, in iter
    raise retry_exc from fut.exception()
tenacity.RetryError: RetryError[<Future at 0x7f195b7f5a50 state=finished raised ConnectionError>]
Traceback (most recent call last):
  File "/home/admin123/frappe-bench/env/lib/python3.10/site-packages/redis/connection.py", line 559, in connect
    sock = self._connect()
  File "/home/admin123/frappe-bench/env/lib/python3.10/site-packages/redis/connection.py", line 615, in _connect
    raise err
  File "/home/admin123/frappe-bench/env/lib/python3.10/site-packages/redis/connection.py", line 603, in _connect
    sock.connect(socket_address)
ConnectionRefusedError: [Errno 111] Connection refused

During handling of the above exception, another exception occurred:

Traceback (most recent call last):
  File "/home/admin123/frappe-bench/env/lib/python3.10/site-packages/tenacity/__init__.py", line 407, in __call__
    result = fn(*args, **kwargs)
  File "/home/admin123/frappe-bench/apps/frappe/frappe/utils/background_jobs.py", line 388, in get_redis_conn
    _redis_queue_conn = RedisQueue.get_connection()
  File "/home/admin123/frappe-bench/apps/frappe/frappe/utils/redis_queue.py", line 24, in get_connection
    conn.ping()
  File "/home/admin123/frappe-bench/env/lib/python3.10/site-packages/redis/client.py", line 1378, in ping
    return self.execute_command('PING')
  File "/home/admin123/frappe-bench/env/lib/python3.10/site-packages/redis/client.py", line 898, in execute_command
    conn = self.connection or pool.get_connection(command_name, **options)
  File "/home/admin123/frappe-bench/env/lib/python3.10/site-packages/redis/connection.py", line 1192, in get_connection
    connection.connect()
  File "/home/admin123/frappe-bench/env/lib/python3.10/site-packages/redis/connection.py", line 563, in connect
    raise ConnectionError(self._error_message(e))
redis.exceptions.ConnectionError: Error 111 connecting to localhost:11000. Connection refused.

The above exception was the direct cause of the following exception:

Traceback (most recent call last):
  File "/usr/lib/python3.10/runpy.py", line 196, in _run_module_as_main
    return _run_code(code, main_globals, None,
  File "/usr/lib/python3.10/runpy.py", line 86, in _run_code
    exec(code, run_globals)
  File "/home/admin123/frappe-bench/apps/frappe/frappe/utils/bench_helper.py", line 109, in <module>
    main()
  File "/home/admin123/frappe-bench/apps/frappe/frappe/utils/bench_helper.py", line 18, in main
    click.Group(commands=commands)(prog_name="bench")
  File "/home/admin123/frappe-bench/env/lib/python3.10/site-packages/click/core.py", line 829, in __call__
    return self.main(*args, **kwargs)
  File "/home/admin123/frappe-bench/env/lib/python3.10/site-packages/click/core.py", line 782, in main
    rv = self.invoke(ctx)
  File "/home/admin123/frappe-bench/env/lib/python3.10/site-packages/click/core.py", line 1259, in invoke
    return _process_result(sub_ctx.command.invoke(sub_ctx))
  File "/home/admin123/frappe-bench/env/lib/python3.10/site-packages/click/core.py", line 1259, in invoke
    return _process_result(sub_ctx.command.invoke(sub_ctx))
  File "/home/admin123/frappe-bench/env/lib/python3.10/site-packages/click/core.py", line 1066, in invoke
    return ctx.invoke(self.callback, **ctx.params)
  File "/home/admin123/frappe-bench/env/lib/python3.10/site-packages/click/core.py", line 610, in invoke
    return callback(*args, **kwargs)
  File "/home/admin123/frappe-bench/apps/frappe/frappe/commands/scheduler.py", line 206, in start_worker
    start_worker(
  File "/home/admin123/frappe-bench/apps/frappe/frappe/utils/background_jobs.py", line 247, in start_worker
    redis_connection = get_redis_conn(username=rq_username, password=rq_password)
  File "/home/admin123/frappe-bench/env/lib/python3.10/site-packages/tenacity/__init__.py", line 324, in wrapped_f
    return self(f, *args, **kw)
  File "/home/admin123/frappe-bench/env/lib/python3.10/site-packages/tenacity/__init__.py", line 404, in __call__
    do = self.iter(retry_state=retry_state)
  File "/home/admin123/frappe-bench/env/lib/python3.10/site-packages/tenacity/__init__.py", line 361, in iter
    raise retry_exc from fut.exception()
tenacity.RetryError: RetryError[<Future at 0x7fdd25ccda50 state=finished raised ConnectionError>]
Traceback (most recent call last):
  File "/home/admin123/frappe-bench/env/lib/python3.10/site-packages/redis/connection.py", line 559, in connect
    sock = self._connect()
  File "/home/admin123/frappe-bench/env/lib/python3.10/site-packages/redis/connection.py", line 615, in _connect
    raise err
  File "/home/admin123/frappe-bench/env/lib/python3.10/site-packages/redis/connection.py", line 603, in _connect
    sock.connect(socket_address)
ConnectionRefusedError: [Errno 111] Connection refused

During handling of the above exception, another exception occurred:

Traceback (most recent call last):
  File "/home/admin123/frappe-bench/env/lib/python3.10/site-packages/tenacity/__init__.py", line 407, in __call__
    result = fn(*args, **kwargs)
  File "/home/admin123/frappe-bench/apps/frappe/frappe/utils/background_jobs.py", line 388, in get_redis_conn
    _redis_queue_conn = RedisQueue.get_connection()
  File "/home/admin123/frappe-bench/apps/frappe/frappe/utils/redis_queue.py", line 24, in get_connection
    conn.ping()
  File "/home/admin123/frappe-bench/env/lib/python3.10/site-packages/redis/client.py", line 1378, in ping
    return self.execute_command('PING')
  File "/home/admin123/frappe-bench/env/lib/python3.10/site-packages/redis/client.py", line 898, in execute_command
    conn = self.connection or pool.get_connection(command_name, **options)
  File "/home/admin123/frappe-bench/env/lib/python3.10/site-packages/redis/connection.py", line 1192, in get_connection
    connection.connect()
  File "/home/admin123/frappe-bench/env/lib/python3.10/site-packages/redis/connection.py", line 563, in connect
    raise ConnectionError(self._error_message(e))
redis.exceptions.ConnectionError: Error 111 connecting to localhost:11000. Connection refused.

The above exception was the direct cause of the following exception:

Traceback (most recent call last):
  File "/usr/lib/python3.10/runpy.py", line 196, in _run_module_as_main
    return _run_code(code, main_globals, None,
  File "/usr/lib/python3.10/runpy.py", line 86, in _run_code
    exec(code, run_globals)
  File "/home/admin123/frappe-bench/apps/frappe/frappe/utils/bench_helper.py", line 109, in <module>
    main()
  File "/home/admin123/frappe-bench/apps/frappe/frappe/utils/bench_helper.py", line 18, in main
    click.Group(commands=commands)(prog_name="bench")
  File "/home/admin123/frappe-bench/env/lib/python3.10/site-packages/click/core.py", line 829, in __call__
    return self.main(*args, **kwargs)
  File "/home/admin123/frappe-bench/env/lib/python3.10/site-packages/click/core.py", line 782, in main
    rv = self.invoke(ctx)
  File "/home/admin123/frappe-bench/env/lib/python3.10/site-packages/click/core.py", line 1259, in invoke
    return _process_result(sub_ctx.command.invoke(sub_ctx))
  File "/home/admin123/frappe-bench/env/lib/python3.10/site-packages/click/core.py", line 1259, in invoke
    return _process_result(sub_ctx.command.invoke(sub_ctx))
  File "/home/admin123/frappe-bench/env/lib/python3.10/site-packages/click/core.py", line 1066, in invoke
    return ctx.invoke(self.callback, **ctx.params)
  File "/home/admin123/frappe-bench/env/lib/python3.10/site-packages/click/core.py", line 610, in invoke
    return callback(*args, **kwargs)
  File "/home/admin123/frappe-bench/apps/frappe/frappe/commands/scheduler.py", line 206, in start_worker
    start_worker(
  File "/home/admin123/frappe-bench/apps/frappe/frappe/utils/background_jobs.py", line 247, in start_worker
    redis_connection = get_redis_conn(username=rq_username, password=rq_password)
  File "/home/admin123/frappe-bench/env/lib/python3.10/site-packages/tenacity/__init__.py", line 324, in wrapped_f
    return self(f, *args, **kw)
  File "/home/admin123/frappe-bench/env/lib/python3.10/site-packages/tenacity/__init__.py", line 404, in __call__
    do = self.iter(retry_state=retry_state)
  File "/home/admin123/frappe-bench/env/lib/python3.10/site-packages/tenacity/__init__.py", line 361, in iter
    raise retry_exc from fut.exception()
tenacity.RetryError: RetryError[<Future at 0x7fd9556c9a50 state=finished raised ConnectionError>]
Traceback (most recent call last):
  File "/home/admin123/frappe-bench/env/lib/python3.10/site-packages/redis/connection.py", line 559, in connect
    sock = self._connect()
  File "/home/admin123/frappe-bench/env/lib/python3.10/site-packages/redis/connection.py", line 615, in _connect
    raise err
  File "/home/admin123/frappe-bench/env/lib/python3.10/site-packages/redis/connection.py", line 603, in _connect
    sock.connect(socket_address)
ConnectionRefusedError: [Errno 111] Connection refused

During handling of the above exception, another exception occurred:

Traceback (most recent call last):
  File "/home/admin123/frappe-bench/env/lib/python3.10/site-packages/tenacity/__init__.py", line 407, in __call__
    result = fn(*args, **kwargs)
  File "/home/admin123/frappe-bench/apps/frappe/frappe/utils/background_jobs.py", line 388, in get_redis_conn
    _redis_queue_conn = RedisQueue.get_connection()
  File "/home/admin123/frappe-bench/apps/frappe/frappe/utils/redis_queue.py", line 24, in get_connection
    conn.ping()
  File "/home/admin123/frappe-bench/env/lib/python3.10/site-packages/redis/client.py", line 1378, in ping
    return self.execute_command('PING')
  File "/home/admin123/frappe-bench/env/lib/python3.10/site-packages/redis/client.py", line 898, in execute_command
    conn = self.connection or pool.get_connection(command_name, **options)
  File "/home/admin123/frappe-bench/env/lib/python3.10/site-packages/redis/connection.py", line 1192, in get_connection
    connection.connect()
  File "/home/admin123/frappe-bench/env/lib/python3.10/site-packages/redis/connection.py", line 563, in connect
    raise ConnectionError(self._error_message(e))
redis.exceptions.ConnectionError: Error 111 connecting to localhost:11000. Connection refused.

The above exception was the direct cause of the following exception:

Traceback (most recent call last):
  File "/usr/lib/python3.10/runpy.py", line 196, in _run_module_as_main
    return _run_code(code, main_globals, None,
  File "/usr/lib/python3.10/runpy.py", line 86, in _run_code
    exec(code, run_globals)
  File "/home/admin123/frappe-bench/apps/frappe/frappe/utils/bench_helper.py", line 109, in <module>
    main()
  File "/home/admin123/frappe-bench/apps/frappe/frappe/utils/bench_helper.py", line 18, in main
    click.Group(commands=commands)(prog_name="bench")
  File "/home/admin123/frappe-bench/env/lib/python3.10/site-packages/click/core.py", line 829, in __call__
    return self.main(*args, **kwargs)
  File "/home/admin123/frappe-bench/env/lib/python3.10/site-packages/click/core.py", line 782, in main
    rv = self.invoke(ctx)
  File "/home/admin123/frappe-bench/env/lib/python3.10/site-packages/click/core.py", line 1259, in invoke
    return _process_result(sub_ctx.command.invoke(sub_ctx))
  File "/home/admin123/frappe-bench/env/lib/python3.10/site-packages/click/core.py", line 1259, in invoke
    return _process_result(sub_ctx.command.invoke(sub_ctx))
  File "/home/admin123/frappe-bench/env/lib/python3.10/site-packages/click/core.py", line 1066, in invoke
    return ctx.invoke(self.callback, **ctx.params)
  File "/home/admin123/frappe-bench/env/lib/python3.10/site-packages/click/core.py", line 610, in invoke
    return callback(*args, **kwargs)
  File "/home/admin123/frappe-bench/apps/frappe/frappe/commands/scheduler.py", line 206, in start_worker
    start_worker(
  File "/home/admin123/frappe-bench/apps/frappe/frappe/utils/background_jobs.py", line 247, in start_worker
    redis_connection = get_redis_conn(username=rq_username, password=rq_password)
  File "/home/admin123/frappe-bench/env/lib/python3.10/site-packages/tenacity/__init__.py", line 324, in wrapped_f
    return self(f, *args, **kw)
  File "/home/admin123/frappe-bench/env/lib/python3.10/site-packages/tenacity/__init__.py", line 404, in __call__
    do = self.iter(retry_state=retry_state)
  File "/home/admin123/frappe-bench/env/lib/python3.10/site-packages/tenacity/__init__.py", line 361, in iter
    raise retry_exc from fut.exception()
tenacity.RetryError: RetryError[<Future at 0x7fb8412cda50 state=finished raised ConnectionError>]
Traceback (most recent call last):
  File "/home/admin123/frappe-bench/env/lib/python3.10/site-packages/redis/connection.py", line 559, in connect
    sock = self._connect()
  File "/home/admin123/frappe-bench/env/lib/python3.10/site-packages/redis/connection.py", line 615, in _connect
    raise err
  File "/home/admin123/frappe-bench/env/lib/python3.10/site-packages/redis/connection.py", line 603, in _connect
    sock.connect(socket_address)
ConnectionRefusedError: [Errno 111] Connection refused

During handling of the above exception, another exception occurred:

Traceback (most recent call last):
  File "/home/admin123/frappe-bench/env/lib/python3.10/site-packages/tenacity/__init__.py", line 407, in __call__
    result = fn(*args, **kwargs)
  File "/home/admin123/frappe-bench/apps/frappe/frappe/utils/background_jobs.py", line 388, in get_redis_conn
    _redis_queue_conn = RedisQueue.get_connection()
  File "/home/admin123/frappe-bench/apps/frappe/frappe/utils/redis_queue.py", line 24, in get_connection
    conn.ping()
  File "/home/admin123/frappe-bench/env/lib/python3.10/site-packages/redis/client.py", line 1378, in ping
    return self.execute_command('PING')
  File "/home/admin123/frappe-bench/env/lib/python3.10/site-packages/redis/client.py", line 898, in execute_command
    conn = self.connection or pool.get_connection(command_name, **options)
  File "/home/admin123/frappe-bench/env/lib/python3.10/site-packages/redis/connection.py", line 1192, in get_connection
    connection.connect()
  File "/home/admin123/frappe-bench/env/lib/python3.10/site-packages/redis/connection.py", line 563, in connect
    raise ConnectionError(self._error_message(e))
redis.exceptions.ConnectionError: Error 111 connecting to localhost:11000. Connection refused.

The above exception was the direct cause of the following exception:

Traceback (most recent call last):
  File "/usr/lib/python3.10/runpy.py", line 196, in _run_module_as_main
    return _run_code(code, main_globals, None,
  File "/usr/lib/python3.10/runpy.py", line 86, in _run_code
    exec(code, run_globals)
  File "/home/admin123/frappe-bench/apps/frappe/frappe/utils/bench_helper.py", line 109, in <module>
    main()
  File "/home/admin123/frappe-bench/apps/frappe/frappe/utils/bench_helper.py", line 18, in main
    click.Group(commands=commands)(prog_name="bench")
  File "/home/admin123/frappe-bench/env/lib/python3.10/site-packages/click/core.py", line 829, in __call__
    return self.main(*args, **kwargs)
  File "/home/admin123/frappe-bench/env/lib/python3.10/site-packages/click/core.py", line 782, in main
    rv = self.invoke(ctx)
  File "/home/admin123/frappe-bench/env/lib/python3.10/site-packages/click/core.py", line 1259, in invoke
    return _process_result(sub_ctx.command.invoke(sub_ctx))
  File "/home/admin123/frappe-bench/env/lib/python3.10/site-packages/click/core.py", line 1259, in invoke
    return _process_result(sub_ctx.command.invoke(sub_ctx))
  File "/home/admin123/frappe-bench/env/lib/python3.10/site-packages/click/core.py", line 1066, in invoke
    return ctx.invoke(self.callback, **ctx.params)
  File "/home/admin123/frappe-bench/env/lib/python3.10/site-packages/click/core.py", line 610, in invoke
    return callback(*args, **kwargs)
  File "/home/admin123/frappe-bench/apps/frappe/frappe/commands/scheduler.py", line 206, in start_worker
    start_worker(
  File "/home/admin123/frappe-bench/apps/frappe/frappe/utils/background_jobs.py", line 247, in start_worker
    redis_connection = get_redis_conn(username=rq_username, password=rq_password)
  File "/home/admin123/frappe-bench/env/lib/python3.10/site-packages/tenacity/__init__.py", line 324, in wrapped_f
    return self(f, *args, **kw)
  File "/home/admin123/frappe-bench/env/lib/python3.10/site-packages/tenacity/__init__.py", line 404, in __call__
    do = self.iter(retry_state=retry_state)
  File "/home/admin123/frappe-bench/env/lib/python3.10/site-packages/tenacity/__init__.py", line 361, in iter
    raise retry_exc from fut.exception()
tenacity.RetryError: RetryError[<Future at 0x7fea79189a50 state=finished raised ConnectionError>]
Traceback (most recent call last):
  File "/home/admin123/frappe-bench/env/lib/python3.10/site-packages/redis/connection.py", line 559, in connect
    sock = self._connect()
  File "/home/admin123/frappe-bench/env/lib/python3.10/site-packages/redis/connection.py", line 615, in _connect
    raise err
  File "/home/admin123/frappe-bench/env/lib/python3.10/site-packages/redis/connection.py", line 603, in _connect
    sock.connect(socket_address)
ConnectionRefusedError: [Errno 111] Connection refused

During handling of the above exception, another exception occurred:

Traceback (most recent call last):
  File "/home/admin123/frappe-bench/env/lib/python3.10/site-packages/tenacity/__init__.py", line 407, in __call__
    result = fn(*args, **kwargs)
  File "/home/admin123/frappe-bench/apps/frappe/frappe/utils/background_jobs.py", line 388, in get_redis_conn
    _redis_queue_conn = RedisQueue.get_connection()
  File "/home/admin123/frappe-bench/apps/frappe/frappe/utils/redis_queue.py", line 24, in get_connection
    conn.ping()
  File "/home/admin123/frappe-bench/env/lib/python3.10/site-packages/redis/client.py", line 1378, in ping
    return self.execute_command('PING')
  File "/home/admin123/frappe-bench/env/lib/python3.10/site-packages/redis/client.py", line 898, in execute_command
    conn = self.connection or pool.get_connection(command_name, **options)
  File "/home/admin123/frappe-bench/env/lib/python3.10/site-packages/redis/connection.py", line 1192, in get_connection
    connection.connect()
  File "/home/admin123/frappe-bench/env/lib/python3.10/site-packages/redis/connection.py", line 563, in connect
    raise ConnectionError(self._error_message(e))
redis.exceptions.ConnectionError: Error 111 connecting to localhost:11000. Connection refused.

The above exception was the direct cause of the following exception:

Traceback (most recent call last):
  File "/usr/lib/python3.10/runpy.py", line 196, in _run_module_as_main
    return _run_code(code, main_globals, None,
  File "/usr/lib/python3.10/runpy.py", line 86, in _run_code
    exec(code, run_globals)
  File "/home/admin123/frappe-bench/apps/frappe/frappe/utils/bench_helper.py", line 109, in <module>
    main()
  File "/home/admin123/frappe-bench/apps/frappe/frappe/utils/bench_helper.py", line 18, in main
    click.Group(commands=commands)(prog_name="bench")
  File "/home/admin123/frappe-bench/env/lib/python3.10/site-packages/click/core.py", line 829, in __call__
    return self.main(*args, **kwargs)
  File "/home/admin123/frappe-bench/env/lib/python3.10/site-packages/click/core.py", line 782, in main
    rv = self.invoke(ctx)
  File "/home/admin123/frappe-bench/env/lib/python3.10/site-packages/click/core.py", line 1259, in invoke
    return _process_result(sub_ctx.command.invoke(sub_ctx))
  File "/home/admin123/frappe-bench/env/lib/python3.10/site-packages/click/core.py", line 1259, in invoke
    return _process_result(sub_ctx.command.invoke(sub_ctx))
  File "/home/admin123/frappe-bench/env/lib/python3.10/site-packages/click/core.py", line 1066, in invoke
    return ctx.invoke(self.callback, **ctx.params)
  File "/home/admin123/frappe-bench/env/lib/python3.10/site-packages/click/core.py", line 610, in invoke
    return callback(*args, **kwargs)
  File "/home/admin123/frappe-bench/apps/frappe/frappe/commands/scheduler.py", line 206, in start_worker
    start_worker(
  File "/home/admin123/frappe-bench/apps/frappe/frappe/utils/background_jobs.py", line 247, in start_worker
    redis_connection = get_redis_conn(username=rq_username, password=rq_password)
  File "/home/admin123/frappe-bench/env/lib/python3.10/site-packages/tenacity/__init__.py", line 324, in wrapped_f
    return self(f, *args, **kw)
  File "/home/admin123/frappe-bench/env/lib/python3.10/site-packages/tenacity/__init__.py", line 404, in __call__
    do = self.iter(retry_state=retry_state)
  File "/home/admin123/frappe-bench/env/lib/python3.10/site-packages/tenacity/__init__.py", line 361, in iter
    raise retry_exc from fut.exception()
tenacity.RetryError: RetryError[<Future at 0x7ff357b89a50 state=finished raised ConnectionError>]
Traceback (most recent call last):
  File "/home/admin123/frappe-bench/env/lib/python3.10/site-packages/redis/connection.py", line 559, in connect
    sock = self._connect()
  File "/home/admin123/frappe-bench/env/lib/python3.10/site-packages/redis/connection.py", line 615, in _connect
    raise err
  File "/home/admin123/frappe-bench/env/lib/python3.10/site-packages/redis/connection.py", line 603, in _connect
    sock.connect(socket_address)
ConnectionRefusedError: [Errno 111] Connection refused

During handling of the above exception, another exception occurred:

Traceback (most recent call last):
  File "/home/admin123/frappe-bench/env/lib/python3.10/site-packages/tenacity/__init__.py", line 407, in __call__
    result = fn(*args, **kwargs)
  File "/home/admin123/frappe-bench/apps/frappe/frappe/utils/background_jobs.py", line 388, in get_redis_conn
    _redis_queue_conn = RedisQueue.get_connection()
  File "/home/admin123/frappe-bench/apps/frappe/frappe/utils/redis_queue.py", line 24, in get_connection
    conn.ping()
  File "/home/admin123/frappe-bench/env/lib/python3.10/site-packages/redis/client.py", line 1378, in ping
    return self.execute_command('PING')
  File "/home/admin123/frappe-bench/env/lib/python3.10/site-packages/redis/client.py", line 898, in execute_command
    conn = self.connection or pool.get_connection(command_name, **options)
  File "/home/admin123/frappe-bench/env/lib/python3.10/site-packages/redis/connection.py", line 1192, in get_connection
    connection.connect()
  File "/home/admin123/frappe-bench/env/lib/python3.10/site-packages/redis/connection.py", line 563, in connect
    raise ConnectionError(self._error_message(e))
redis.exceptions.ConnectionError: Error 111 connecting to localhost:11000. Connection refused.

The above exception was the direct cause of the following exception:

Traceback (most recent call last):
  File "/usr/lib/python3.10/runpy.py", line 196, in _run_module_as_main
    return _run_code(code, main_globals, None,
  File "/usr/lib/python3.10/runpy.py", line 86, in _run_code
    exec(code, run_globals)
  File "/home/admin123/frappe-bench/apps/frappe/frappe/utils/bench_helper.py", line 109, in <module>
    main()
  File "/home/admin123/frappe-bench/apps/frappe/frappe/utils/bench_helper.py", line 18, in main
    click.Group(commands=commands)(prog_name="bench")
  File "/home/admin123/frappe-bench/env/lib/python3.10/site-packages/click/core.py", line 829, in __call__
    return self.main(*args, **kwargs)
  File "/home/admin123/frappe-bench/env/lib/python3.10/site-packages/click/core.py", line 782, in main
    rv = self.invoke(ctx)
  File "/home/admin123/frappe-bench/env/lib/python3.10/site-packages/click/core.py", line 1259, in invoke
    return _process_result(sub_ctx.command.invoke(sub_ctx))
  File "/home/admin123/frappe-bench/env/lib/python3.10/site-packages/click/core.py", line 1259, in invoke
    return _process_result(sub_ctx.command.invoke(sub_ctx))
  File "/home/admin123/frappe-bench/env/lib/python3.10/site-packages/click/core.py", line 1066, in invoke
    return ctx.invoke(self.callback, **ctx.params)
  File "/home/admin123/frappe-bench/env/lib/python3.10/site-packages/click/core.py", line 610, in invoke
    return callback(*args, **kwargs)
  File "/home/admin123/frappe-bench/apps/frappe/frappe/commands/scheduler.py", line 206, in start_worker
    start_worker(
  File "/home/admin123/frappe-bench/apps/frappe/frappe/utils/background_jobs.py", line 247, in start_worker
    redis_connection = get_redis_conn(username=rq_username, password=rq_password)
  File "/home/admin123/frappe-bench/env/lib/python3.10/site-packages/tenacity/__init__.py", line 324, in wrapped_f
    return self(f, *args, **kw)
  File "/home/admin123/frappe-bench/env/lib/python3.10/site-packages/tenacity/__init__.py", line 404, in __call__
    do = self.iter(retry_state=retry_state)
  File "/home/admin123/frappe-bench/env/lib/python3.10/site-packages/tenacity/__init__.py", line 361, in iter
    raise retry_exc from fut.exception()
tenacity.RetryError: RetryError[<Future at 0x7fe2402f9a50 state=finished raised ConnectionError>]
Exception in thread Thread-1:
Traceback (most recent call last):
  File "/usr/lib/python3.10/threading.py", line 1016, in _bootstrap_inner
    self.run()
  File "/home/admin123/frappe-bench/env/lib/python3.10/site-packages/redis/client.py", line 3718, in run
    pubsub.get_message(ignore_subscribe_messages=True,
  File "/home/admin123/frappe-bench/env/lib/python3.10/site-packages/redis/client.py", line 3617, in get_message
    response = self.parse_response(block=False, timeout=timeout)
  File "/home/admin123/frappe-bench/env/lib/python3.10/site-packages/redis/client.py", line 3503, in parse_response
    if not block and not conn.can_read(timeout=timeout):
  File "/home/admin123/frappe-bench/env/lib/python3.10/site-packages/redis/connection.py", line 734, in can_read
    return self._parser.can_read(timeout)
  File "/home/admin123/frappe-bench/env/lib/python3.10/site-packages/redis/connection.py", line 416, in can_read
    return self.read_from_socket(timeout=timeout,
  File "/home/admin123/frappe-bench/env/lib/python3.10/site-packages/redis/connection.py", line 429, in read_from_socket
    raise ConnectionError(SERVER_CLOSED_CONNECTION_ERROR)
redis.exceptions.ConnectionError: Connection closed by server.
Exception in thread Thread-1:
Traceback (most recent call last):
  File "/usr/lib/python3.10/threading.py", line 1016, in _bootstrap_inner
    self.run()
  File "/home/admin123/frappe-bench/env/lib/python3.10/site-packages/redis/client.py", line 3718, in run
    pubsub.get_message(ignore_subscribe_messages=True,
  File "/home/admin123/frappe-bench/env/lib/python3.10/site-packages/redis/client.py", line 3617, in get_message
    response = self.parse_response(block=False, timeout=timeout)
  File "/home/admin123/frappe-bench/env/lib/python3.10/site-packages/redis/client.py", line 3503, in parse_response
    if not block and not conn.can_read(timeout=timeout):
  File "/home/admin123/frappe-bench/env/lib/python3.10/site-packages/redis/connection.py", line 734, in can_read
    return self._parser.can_read(timeout)
  File "/home/admin123/frappe-bench/env/lib/python3.10/site-packages/redis/connection.py", line 416, in can_read
    return self.read_from_socket(timeout=timeout,
  File "/home/admin123/frappe-bench/env/lib/python3.10/site-packages/redis/connection.py", line 429, in read_from_socket
    raise ConnectionError(SERVER_CLOSED_CONNECTION_ERROR)
redis.exceptions.ConnectionError: Connection closed by server.
